Workbook

Sheet Sheet1
O3: q0 | P3: 5000 | Q3: STB/d | S3: qw | T3: 0 | U3: STB water/STB
O4: WOR | P4: 0 | Q4: STB Water/STB | S4: s oil | T4: 30 | U4: dyne/cm
O5: GLR | P5: 250 | Q5: scf/STB | S5: g w | T5: 1.074
O6: g g | P6: 0.71 | S6: r w | T6: =T5*62.4 -> 67.0176 | U6: lbm/ft3
O7: Psep | P7: 100 | Q7: psig | S7: m w | T7: 1 | U7: cp
O8: g sep | P8: 0.71 | S8: sw | T8: 72 | U8: dyne/cm
O9: g l | P9: 32 | Q9: 0API | S9: D | T9: =4/12 -> 0.33333333 | U9: ft
O10: GOR | P10: 250 | Q10: scf/STB | S10: Area | T10: =(3.1416/4)*(T9)^2 -> 0.087266667 | U10: ft2
O11: ql | P11: =P3+T3 -> 5000 | Q11: STB/d
O12: qg | P12: =P5*P11 -> 1250000 | Q12: scf/d | W12: Rs | X12: g gd | Y12: slope | CT12: A1 | CU12: 0.3265 | CV12: A2 | CW12: -1.07 | CX12: A3 | CY12: =-0.5339 -> -0.5339 | CZ12: A4 | DA12: =0.01569 -> 0.01569 | DB12: A5 | DC12: =-0.05165 -> -0.05165 | DD12: A6 | DE12: 0.5475 | DF12: A7 | DG12: -0.7361
W13: 1400 | X13: 0.73 | Y13: =SLOPE(X13:X14,W13:W14) -> -0.00011428571 | CT13: A8 | CU13: =0.1844 -> 0.1844 | CV13: A9 | CW13: =0.1056 -> 0.1056 | CX13: A10 | CY13: =0.6134 -> 0.6134 | CZ13: A11 | DA13: 0.721
W14: 0 | X14: 0.89 | AQ14: From DAK | CH14: DL | CI14: 200 | CJ14: ft | CN14: DAK Correlation | EI14: LGE Correlation
CA15: e | CB15: 0.0006 | CC15: (assumed) | EZ15: From Graph
N16: Const. T | P16: Const. T | V16: from fig:3.4 | BS16: For qg=0 or <1 | BT16: For yl >1 | BU16: For GLR=0 | EZ16: GLR=400 | FC16: GLR=0
C17: P (psia) | D17: P (assumed) | E17: P (output) | F17: Err | G17: p(avg) | I17: P (OUTPUT) | K17: P (avg) | L17: T0F (const.) | M17: T0 R (const.) | N17: A | O17: Rs (scf/STB) | P17: F | Q17: B0 (res bbl/STB) | R17: Bg (res ft3/SCF) | S17: ql (res bbl/d) | T17: ql (res ft3/d) | U17: qg (res ft3/d) | V17: γgd | W17: ρ0 (part1) | X17: ρ0 (part 2) | Y17: ρ0 (lb / ft3) | Z17: ρl (part 1) | AA17: ρl (part 2) | AB17: ρl (lbm/ft3) | AC17: C | AD17: B | AE17: A | AF17: m od | AG17: a | AH17: b | AI17: m o (cp) | AJ17: Weight 1 | AK17: Weight 2 | AL17: ml (cp) | AM17: weight 1 | AN17: weight 2 | AO17: s l (dyne/cm) | AQ17: Ppr | AR17: Tpr | AS17: Z | AU17: usl (ft/s) | AV17: usg (ft/s) | AW17: um (ft/s) | AX17: l l | AY17: l g | AZ17: LB | BA17: LB(final) | BB17: Nvl | BC17: Nvg | BD17: ND | BE17: NL | BF17: CNL(1) | BG17: CNL(2) | BH17: CNL | BI17: H(1) | BJ17: H(2) | BK17: H | BL17: y1/(1) | BM17: y1/(2) | BN17: y1/ | BO17: B | BP17: (1) | BQ17: (2) | BR17:  | BS17: yl | BT17: yl | BU17: yl | BV17: m(1) | BW17: m(2) | BX17: m (lbm/d) | BY17: m m | BZ17: Nre | CA17: f(1) | CB17: f(2) | CC17: f(3) | CD17: 1/sqrt(f) | CE17: f | CF17: r(avg) | CG17: fm2/D5rho | CH17: dp/dl | CI17: DP | CJ17: L | CK17: P (psi) | CN17: T (0F) | CO17: T (0R) | CP17: Tc (0R) | CQ17: Pc | CR17: Tpr | CS17: Ppr | CT17: Z | CU17: ρpr | CV17: Part 1 | CW17: Part 2 | CX17: Part 3 | CY17: Part 4 | CZ17: Part 5 | DA17: Z(1) | DB17: Err(1) | DC17: Z | DD17: ρpr | DE17: Part 1 | DF17: Part 2 | DG17: Part 3 | DH17: Part 4 | DI17: Part 5 | DJ17: Z(2) | DK17: Err(2) | DL17: Slope | DM17: Z | DN17: Z | DO17: ρpr | DP17: Part 1 | DQ17: Part 2 | DR17: Part 3 | DS17: Part 4 | DT17: Part 5 | DU17: Z(1) | DV17: Err(1) | DW17: Z | DX17: ρpr | DY17: Part 1 | DZ17: Part 2 | EA17: Part 3 | EB17: Part 4 | EC17: Part 5 | ED17: Z(2) | EE17: Err(2) | EF17: Slope | EG17: Z | EI17: T (0F) | EJ17: T (0R) | EK17: P (psi) | EL17: Tc (0R) | EM17: Pc (psi) | EN17: γg | EO17: MW | EP17: A1 | EQ17: A2 | ER17: A | ES17: B | ET17: C | EU17: ρg (lbm/ft3) | EV17: ρg (g/cm3) | EW17: EXP(Bρgc) | EX17: µg (cp) | EZ17: Pressure | FA17: Depth | FC17: Pressure | FD17: Depth
C18: 314.7 | D18: 314.8 | E18: =CK18 -> 342.91335 | F18: =D18-E18 -> -28.113346 | G18: =AVERAGE(C18,D18) -> 314.75 | I18: =Sheet10!K18 -> 328.59637 | K18: =G18 -> 314.75 | L18: 220 | M18: =460+L18 -> 680 | N18: =$P$9/($L$18+460) -> 0.047058824 | O18: =(($P$8*K18^1.187)/56.06)*10^(10.393*$N$18) -> 36.039017 | P18: =($L$18-60)*($P$9/$P$8) -> 7211.2676 | Q18: =1+(4.67*10^-4*O18)+(0.11*10^-4*$P$18)+(0.1337*10^-8*O18*$P$18) -> 1.0965016 | R18: =0.0283*AS18*($M$18)/K18 -> 0.059690383 | S18: =$P$3*($P$4+Q18) -> 5482.5082 | T18: =S18*5.615 -> 30784.283 | U18: =IF($P$5>0,R18*($P$10-O18)*$P$3,0) -> 63857.065 | V18: =$X$14+$Y$13*(O18-$W$14) -> 0.88588126 | W18: =(8830/(131.5+$P$9)) -> 54.006116 | X18: =0.01361*V18*O18 -> 0.43451681 | Y18: =(W18+X18)/Q18 -> 49.649386 | Z18: =($T$6*$P$4)+(Q18*Y18) -> 54.440633 | AA18: =$P$4+Q18 -> 1.0965016 | AB18: =Z18/AA18 -> 49.649386 | AC18: =3.0324-0.02023*$P$9 -> 2.38504 | AD18: =10^$AC$18 -> 242.68336 | AE18: =$AD$18*$L$18^-1.163 -> 0.45793351 | AF18: =10^$AE$18-1 -> 1.8703411 | AG18: =10.715*(O18+100)^-0.515 -> 0.85340558 | AH18: =5.44*(O18+150)^-0.338 -> 0.92997813 | AI18: =AG18*$AF$18^AH18 -> 1.5276923 | AJ18: =(($P$4*$T$6)/($P$4*$T$6+Q18*Y18))*$T$7 -> 0 | AK18: =((Q18*Y18)/($P$4*$T$6+Q18*Y18))*AI18 -> 1.5276923 | AL18: =AJ18+AK18 -> 1.5276923 | AM18: =(($P$4*$T$6)/($P$4*$T$6+Q18*Y18))*$T$8 -> 0 | AN18: =((Q18*Y18)/($P$4*$T$6+Q18*Y18))*$T$4 -> 30 | AO18: =AM18+AN18 -> 30 | AQ18: =CS18 -> 0.47188906 | AR18: =CR18 -> 1.8181818 | AS18: =EG18 -> 0.97628081 | AU18: =(T18)*(1/86400)/$T$10 -> 4.0828828 | AV18: =(U18)*(1/86400)/$T$10 -> 8.4692864 | AW18: =AU18+AV18 -> 12.552169 | AX18: =AU18/AW18 -> 0.32527309 | AY18: =1-AX18 -> 0.67472691 | AZ18: =1.071-(0.2218*((AW18^2)/($T$9))) -> -103.7674 | BA18: =IF(AZ18<0.13,0.13,AZ18) -> 0.13 | BB18: =1.938*AU18*(AB18/AO18)^(1/4) -> 8.9746774 | BC18: =1.938*AV18*(AB18/AO18)^(1/4) -> 18.616531 | BD18: =120.872*$T$9*SQRT(AB18/AO18) -> 51.832334 | BE18: =0.15726*AL18*(1/(AB18*AO18^3))^(1/4) -> 0.0070604885 | BF18: =0.0019+0.0322*BE18-0.6642*BE18^2+4.9951*BE18^3 -> 0.0020959951 | BG18: =1-10.0147*BE18+33.8696*BE18^2+277.2817*BE18^3 -> 0.93107734 | BH18: =BF18/BG18 -> 0.0022511504 | BI18: =BB18*($K$18^0.1)*BH18 -> 0.035910375 | BJ18: =(BC18^0.575)*(14.7^0.1)*BD18 -> 364.35462 | BK18: =BI18/BJ18 -> 9.8558856e-05 | BL18: =(0.0047+1123.32*BK18+729489.64*BK18^2) -> 0.12249929 | BM18: =(1+1097.1566*BK18+722153.97*BK18^2) -> 1.1151494 | BN18: =SQRT(BL18/BM18) -> 0.33143644 | BO18: =(BC18*BE18^0.38)/BD18^2.14 -> 0.00060703022 | BP18: =1.0886-69.9473*BO18+2334.3497*BO18^2-12896.683*BO18^3 -> 1.0469972 | BQ18: =1-53.4401*BO18+1517.9369*BO18^2-8419.8115*BO18^3 -> 0.9681177 | BR18: =BP18/BQ18 -> 1.0814771 | BS18: =IF(U18<=0,1,(BN18*BR18)) -> 0.35844093 | BT18: =IF(U18>1,BN18*BR18,1) -> 0.35844093 | BU18: =IF($P$5=0,1,BT18) -> 0.35844093 | BV18: =AB18*AU18 -> 202.71263 | BW18: =EU18*AV18 -> 7.0418839 | BX18: =$T$10*(BV18+BW18)*86400 -> 1581515.4 | BY18: =(AL18^BS18)*EX18^(1-BS18) -> 0.075031752 | BZ18: =2.2*10^-2*BX18/BY18/$T$9 -> 1391144.6 | CA18: =$CB$15/3.7065 -> 0.00016187778 | CB18: =5.0452/BZ18 -> 3.6266538e-06 | CC18: =LOG(($CB$15^1.1098/2.8257)+(7.149/BZ18)^0.8981) -> -3.9515349 | CD18: =-4*LOG(CA18-(CB18*CC18)) -> 15.015891 | CE18: =1/CD18^2 -> 0.0044350423 | CF18: =BS18*AB18+(1-BS18)*EU18 -> 18.329804 | CG18: =CE18*BX18^2/($T$9)^5/CF18 -> 1.4705951e+11 | CH18: =(1/144)*(CF18+(CG18/74130000000)) -> 0.14106673 | CI18: =CH18*$CI$14 -> 28.213346 | CJ18: 200 | CK18: =C18+CI18 -> 342.91335 | CN18: =L18 -> 220 | CO18: =CN18+460 -> 680 | CP18: 374 | CQ18: 667 | CR18: =CO18/CP18 -> 1.8181818 | CS18: =K18/$CQ$18 -> 0.47188906 | CT18: 0.8 | CU18: =0.27*CS18/CT18/$CR$18 -> 0.087594406 | CV18: =($CU$12+$CW$12/$CR$18+$CY$12/$CR$18^3+$DA$12/$CR$18^4+$DC$12/$CR$18^5)*CU18 -> -0.030832473 | CW18: =($DE$12+$DG$12/$CR$18+$CU$13/$CR$18^2)*CU18^2 -> 0.001522479 | CX18: =$CW$13*($DG$12/$CR$18+$CU$13/$CR$18^2)*CU18^5 -> -1.9009175e-07 | CY18: =$CY$13*(1+$DA$13*CU18^2)*(CU18^2/$CR$18^3) -> 0.00078737299 | CZ18: =EXP(-$DA$13*CU18^2) -> 0.9944832 | DA18: =1+CV18+CW18-CX18+CY18*CZ18 -> 0.97147323 | DB18: =DA18-CT18 -> 0.17147323 | DC18: 0.85 | DD18: =0.27*CS18/DC18/$CR$18 -> 0.082441794 | DE18: =($CU$12+$CW$12/$CR$18+$CY$12/$CR$18^3+$DA$12/$CR$18^4+$DC$12/$CR$18^5)*DD18 -> -0.029018798 | DF18: =($DE$12+$DG$12/$CR$18+$CU$13/$CR$18^2)*DD18^2 -> 0.0013486319 | DG18: =$CW$13*($DG$12/$CR$18+$CU$13/$CR$18^2)*DD18^5 -> -1.4038431e-07 | DH18: =$CY$13*(1+$DA$13*DD18^2)*DD18^2/$CR$18^3 -> 0.00069702719 | DI18: =EXP(-$DA$13*DD18^2) -> 0.9951116 | DJ18: =1+DE18+DF18-DG18+DH18*DI18 -> 0.97302359 | DK18: =DJ18-DC18 -> 0.12302359 | DL18: =(DK18-DB18)/(DC18-CT18) -> -0.96899263 | DM18: =CT18-DB18/DL18 -> 0.9769603 | DN18: =DC18 -> 0.85 | DO18: =0.27*CS18/DN18/$CR$18 -> 0.082441794 | DP18: =($CU$12+$CW$12/$CR$18+$CY$12/$CR$18^3+$DA$12/$CR$18^4+$DC$12/$CR$18^5)*DO18 -> -0.029018798 | DQ18: =($DE$12+$DG$12/$CR$18+$CU$13/$CR$18^2)*DO18^2 -> 0.0013486319 | DR18: =$CW$13*($DG$12/$CR$18+$CU$13/$CR$18^2)*DO18^5 -> -1.4038431e-07 | DS18: =$CY$13*(1+$DA$13*DO18^2)*(DO18^2/$CR$18^3) -> 0.00069702719 | DT18: =EXP(-$DA$13*DO18^2) -> 0.9951116 | DU18: =1+DP18+DQ18-DR18+DS18*DT18 -> 0.97302359 | DV18: =DU18-DN18 -> 0.12302359 | DW18: =DM18 -> 0.9769603 | DX18: =0.27*CS18/DW18/$CR$18 -> 0.071728119 | DY18: =($CU$12+$CW$12/$CR$18+$CY$12/$CR$18^3+$DA$12/$CR$18^4+$DC$12/$CR$18^5)*DX18 -> -0.025247677 | DZ18: =($DE$12+$DG$12/$CR$18+$CU$13/$CR$18^2)*DX18^2 -> 0.0010208865 | EA18: =$CW$13*($DG$12/$CR$18+$CU$13/$CR$18^2)*DX18^5 -> -6.9988814e-08 | EB18: =$CY$13*(1+$DA$13*DX18^2)*DX18^2/$CR$18^3 -> 0.00052700988 | EC18: =EXP(-$DA$13*DX18^2) -> 0.99629738 | ED18: =1+DY18+DZ18-EA18+EB18*EC18 -> 0.97629834 | EE18: =ED18-DW18 -> -0.00066196186 | EF18: =(EE18-DV18)/(DW18-DN18) -> -0.97420655 | EG18: =DN18-DV18/EF18 -> 0.97628081 | EI18: =L18 -> 220 | EJ18: =460+EI18 -> 680 | EK18: =K18 -> 314.75 | EL18: =CP18 -> 374 | EM18: =CQ18 -> 667 | EN18: 0.65 | EO18: =28.97*$EN$18 -> 18.8305 | EP18: =((9.379+0.01607*$EO$18)*$EJ$18^1.5) -> 171676.47 | EQ18: =209.2+19.26*EO18+EJ18 -> 1251.8754 | ER18: =EP18/EQ18 -> 137.13543 | ES18: =3.448+(986.4/EJ18)+0.01009*EO18 -> 5.088588 | ET18: =2.447-0.2224*ES18 -> 1.315298 | EU18: =(EK18*$EO$18)/(DM18*10.73*$EJ$18) -> 0.8314613 | EV18: =EU18/67.0176 -> 0.012406611 | EW18: =EXP($ES$18*EV18^$ET$18) -> 1.0159449 | EX18: =$ER$18*10^-4*EW18 -> 0.013932204 | EZ18: 84.5 | FA18: 38.9 | FC18: 108.5 | FD18: 20.1
C19: =E18 -> 342.91335 | D19: 314.9 | E19: =CK19 -> 371.46297 | F19: =D19-E19 -> -56.562967 | G19: =AVERAGE(C19,D19) -> 328.90667 | I19: =Sheet10!K19 -> 357.86415 | K19: =G19 -> 328.90667 | O19: =(($P$8*K19^1.187)/56.06)*10^(10.393*$N$18) -> 37.971074 | Q19: =1+(4.67*10^-4*O19)+(0.11*10^-4*$P$18)+(0.1337*10^-8*O19*$P$18) -> 1.0974225 | R19: =0.0283*AS19*($M$18)/K19 -> 0.057061645 | S19: =$P$3*($P$4+Q19) -> 5487.1127 | T19: =S19*5.615 -> 30810.138 | U19: =IF($P$5>0,R19*($P$10-O19)*$P$3,0) -> 60493.596 | V19: =$X$14+$Y$13*(O19-$W$14) -> 0.88566045 | W19: =(8830/(131.5+$P$9)) -> 54.006116 | X19: =0.01361*V19*O19 -> 0.45769721 | Y19: =(W19+X19)/Q19 -> 49.628846 | Z19: =($P$4*$T$6)+(Q19*Y19) -> 54.463813 | AA19: =$P$4+Q19 -> 1.0974225 | AB19: =Z19/AA19 -> 49.628846 | AG19: =10.715*(O19+100)^-0.515 -> 0.84723001 | AH19: =5.44*(O19+150)^-0.338 -> 0.92673621 | AI19: =AG19*$AF$18^AH19 -> 1.5135619 | AJ19: =(($P$4*$T$6)/($P$4*$T$6+Q19*Y19))*$T$7 -> 0 | AK19: =((Q19*Y19)/($P$4*$T$6+Q19*Y19))*AI19 -> 1.5135619 | AL19: =AJ19+AK19 -> 1.5135619 | AM19: =(($P$4*$T$6)/($P$4*$T$6+Q19*Y19))*$T$8 -> 0 | AN19: =((Q19*Y19)/($P$4*$T$6+Q19*Y19))*$T$4 -> 30 | AO19: =AM19+AN19 -> 30 | AQ19: =CS19 -> 0.49311345 | AS19: =EG19 -> 0.97526272 | AU19: =(T19)*(1/86400)/$T$10 -> 4.0863119 | AV19: =(U19)*(1/86400)/$T$10 -> 8.0231936 | AW19: =AU19+AV19 -> 12.109505 | AX19: =AU19/AW19 -> 0.33744663 | AY19: =1-AX19 -> 0.66255337 | AZ19: =1.071-(0.2218*((AW19^2)/($T$9))) -> -96.503338 | BA19: =IF(AZ19<0.13,0.13,AZ19) -> 0.13 | BB19: =1.938*AU19*(AB19/AO19)^(1/4) -> 8.9812857 | BC19: =1.938*AV19*(AB19/AO19)^(1/4) -> 17.63414 | BD19: =120.872*$T$9*SQRT(AB19/AO19) -> 51.821611 | BE19: =0.15726*AL19*(1/(AB19*AO19^3))^(1/4) -> 0.0069959063 | BF19: =0.0019+0.0322*BE19-0.6642*BE19^2+4.9951*BE19^3 -> 0.0020944708 | BG19: =1-10.0147*BE19+33.8696*BE19^2+277.2817*BE19^3 -> 0.93169071 | BH19: =BF19/BG19 -> 0.0022480322 | BI19: =BB19*($K$18^0.1)*BH19 -> 0.035887038 | BJ19: =(BC19^0.575)*(14.7^0.1)*BD19 -> 353.09889 | BK19: =BI19/BJ19 -> 0.00010163453 | BL19: =(0.0047+1123.32*BK19+729489.64*BK19^2) -> 0.12640341 | BM19: =(1+1097.1566*BK19+722153.97*BK19^2) -> 1.1189685 | BN19: =SQRT(BL19/BM19) -> 0.33610151 | BO19: =(BC19*BE19^0.38)/BD19^2.14 -> 0.0005732468 | BP19: =1.0886-69.9473*BO19+2334.3497*BO19^2-12896.683*BO19^3 -> 1.0492676 | BQ19: =1-53.4401*BO19+1517.9369*BO19^2-8419.8115*BO19^3 -> 0.96986286 | BR19: =BP19/BQ19 -> 1.0818721 | BS19: =IF(U19<=0,1,(BN19*BR19)) -> 0.36361886 | BT19: =IF(U19>1,BN19*BR19,1) -> 0.36361886 | BU19: =IF($P$5=0,1,BT19) -> 0.36361886 | BV19: =AB19*AU19 -> 202.79894 | BW19: =EU19*AV19 -> 6.9781901 | BX19: =$T$10*(BV19+BW19)*86400 -> 1581686 | BY19: =(AL19^BS19)*EX19^(1-BS19) -> 0.076666815 | BZ19: =2.2*10^-2*BX19/BY19/$T$9 -> 1361622.7 | CA19: =$CB$15/3.7065 -> 0.00016187778 | CB19: =5.0452/BZ19 -> 3.7052849e-06 | CC19: =LOG(($CB$15^1.1098/2.8257)+(7.149/BZ19)^0.8981) -> -3.9501939 | CD19: =-4*LOG(CA19-(CB19*CC19)) -> 15.01288 | CE19: =1/CD19^2 -> 0.0044368219 | CF19: =BS19*AB19+(1-BS19)*EU19 -> 18.599478 | CG19: =CE19*BX19^2/($T$9)^5/CF19 -> 1.4501671e+11 | CH19: =(1/144)*(CF19+(CG19/74130000000)) -> 0.1427481 | CI19: =CH19*$CI$14 -> 28.54962 | CJ19: =CJ18+200 -> 400 | CK19: =C19+CI19 -> 371.46297 | CS19: =K19/$CQ$18 -> 0.49311345 | CT19: 0.8 | CU19: =0.27*CS19/CT19/$CR$18 -> 0.091534185 | CV19: =($CU$12+$CW$12/$CR$18+$CY$12/$CR$18^3+$DA$12/$CR$18^4+$DC$12/$CR$18^5)*CU19 -> -0.032219241 | CW19: =($DE$12+$DG$12/$CR$18+$CU$13/$CR$18^2)*CU19^2 -> 0.0016625136 | CX19: =$CW$13*($DG$12/$CR$18+$CU$13/$CR$18^2)*CU19^5 -> -2.3686343e-07 | CY19: =$CY$13*(1+$DA$13*CU19^2)*(CU19^2/$CR$18^3) -> 0.00086022907 | CZ19: =EXP(-$DA$13*CU19^2) -> 0.99397731 | DA19: =1+CV19+CW19-CX19+CY19*CZ19 -> 0.97029856 | DB19: =DA19-CT19 -> 0.17029856 | DC19: 0.85 | DD19: =0.27*CS19/DC19/$CR$18 -> 0.086149821 | DE19: =($CU$12+$CW$12/$CR$18+$CY$12/$CR$18^3+$DA$12/$CR$18^4+$DC$12/$CR$18^5)*DD19 -> -0.030323991 | DF19: =($DE$12+$DG$12/$CR$18+$CU$13/$CR$18^2)*DD19^2 -> 0.0014726764 | DG19: =$CW$13*($DG$12/$CR$18+$CU$13/$CR$18^2)*DD19^5 -> -1.7492558e-07 | DH19: =$CY$13*(1+$DA$13*DD19^2)*DD19^2/$CR$18^3 -> 0.00076147975 | DI19: =EXP(-$DA$13*DD19^2) -> 0.99466318 | DJ19: =1+DE19+DF19-DG19+DH19*DI19 -> 0.97190628 | DK19: =DJ19-DC19 -> 0.12190628 | DL19: =(DK19-DB19)/(DC19-CT19) -> -0.96784564 | DM19: =CT19-DB19/DL19 -> 0.97595632 | DN19: =DC19 -> 0.85 | DO19: =0.27*CS19/DN19/$CR$18 -> 0.086149821 | DP19: =($CU$12+$CW$12/$CR$18+$CY$12/$CR$18^3+$DA$12/$CR$18^4+$DC$12/$CR$18^5)*DO19 -> -0.030323991 | DQ19: =($DE$12+$DG$12/$CR$18+$CU$13/$CR$18^2)*DO19^2 -> 0.0014726764 | DR19: =$CW$13*($DG$12/$CR$18+$CU$13/$CR$18^2)*DO19^5 -> -1.7492558e-07 | DS19: =$CY$13*(1+$DA$13*DO19^2)*(DO19^2/$CR$18^3) -> 0.00076147975 | DT19: =EXP(-$DA$13*DO19^2) -> 0.99466318 | DU19: =1+DP19+DQ19-DR19+DS19*DT19 -> 0.97190628 | DV19: =DU19-DN19 -> 0.12190628 | DW19: =DM19 -> 0.97595632 | DX19: =0.27*CS19/DW19/$CR$18 -> 0.075031378 | DY19: =($CU$12+$CW$12/$CR$18+$CY$12/$CR$18^3+$DA$12/$CR$18^4+$DC$12/$CR$18^5)*DX19 -> -0.026410396 | DZ19: =($DE$12+$DG$12/$CR$18+$CU$13/$CR$18^2)*DX19^2 -> 0.0011170804 | EA19: =$CW$13*($DG$12/$CR$18+$CU$13/$CR$18^2)*DX19^5 -> -8.7658904e-08 | EB19: =$CY$13*(1+$DA$13*DX19^2)*DX19^2/$CR$18^3 -> 0.00057686864 | EC19: =EXP(-$DA$13*DX19^2) -> 0.99594921 | ED19: =1+DY19+DZ19-EA19+EB19*EC19 -> 0.9752813 | EE19: =ED19-DW19 -> -0.00067501665 | EF19: =(EE19-DV19)/(DW19-DN19) -> -0.97320477 | EG19: =DN19-DV19/EF19 -> 0.97526272 | EK19: =K19 -> 328.90667 | EU19: =(EK19*$EO$18)/(DM19*10.73*$EJ$18) -> 0.86975217 | EV19: =EU19/67.0176 -> 0.012977967 | EW19: =EXP($ES$18*EV19^$ET$18) -> 1.0169259 | EX19: =$ER$18*10^-4*EW19 -> 0.013945657 | EZ19: 190.6 | FA19: 803.1 | FC19: 240 | FD19: 366
C20: =E19 -> 371.46297 | D20: 315 | E20: =CK20 -> 400.34707 | F20: =D20-E20 -> -85.347072 | G20: =AVERAGE(C20,D20) -> 343.23148 | I20: =Sheet10!K20 -> 387.79841 | K20: =G20 -> 343.23148 | O20: =(($P$8*K20^1.187)/56.06)*10^(10.393*$N$18) -> 39.941973 | Q20: =1+(4.67*10^-4*O20)+(0.11*10^-4*$P$18)+(0.1337*10^-8*O20*$P$18) -> 1.0983619 | R20: =0.0283*AS20*($M$18)/K20 -> 0.054622672 | S20: =$P$3*($P$4+Q20) -> 5491.8097 | T20: =S20*5.615 -> 30836.512 | U20: =IF($P$5>0,R20*($P$10-O20)*$P$3,0) -> 57369.653 | V20: =$X$14+$Y$13*(O20-$W$14) -> 0.8854352 | W20: =(8830/(131.5+$P$9)) -> 54.006116 | X20: =0.01361*V20*O20 -> 0.48133166 | Y20: =(W20+X20)/Q20 -> 49.607917 | Z20: =($P$4*$T$6)+(Q20*Y20) -> 54.487448 | AA20: =$P$4+Q20 -> 1.0983619 | AB20: =Z20/AA20 -> 49.607917 | AG20: =10.715*(O20+100)^-0.515 -> 0.84106383 | AH20: =5.44*(O20+150)^-0.338 -> 0.92347474 | AI20: =AG20*$AF$18^AH20 -> 1.499481 | AJ20: =(($P$4*$T$6)/($P$4*$T$6+Q20*Y20))*$T$7 -> 0 | AK20: =((Q20*Y20)/($P$4*$T$6+Q20*Y20))*AI20 -> 1.499481 | AL20: =AJ20+AK20 -> 1.499481 | AM20: =(($P$4*$T$6)/($P$4*$T$6+Q20*Y20))*$T$8 -> 0 | AN20: =((Q20*Y20)/($P$4*$T$6+Q20*Y20))*$T$4 -> 30 | AO20: =AM20+AN20 -> 30 | AQ20: =CS20 -> 0.51458993 | AS20: =EG20 -> 0.9742372 | AU20: =(T20)*(1/86400)/$T$10 -> 4.0898098 | AV20: =(U20)*(1/86400)/$T$10 -> 7.6088688 | AW20: =AU20+AV20 -> 11.698679 | AX20: =AU20/AW20 -> 0.34959588 | AY20: =1-AX20 -> 0.65040412 | AZ20: =1.071-(0.2218*((AW20^2)/($T$9))) -> -89.995033 | BA20: =IF(AZ20<0.13,0.13,AZ20) -> 0.13 | BB20: =1.938*AU20*(AB20/AO20)^(1/4) -> 8.988026 | BC20: =1.938*AV20*(AB20/AO20)^(1/4) -> 16.721734 | BD20: =120.872*$T$9*SQRT(AB20/AO20) -> 51.810683 | BE20: =0.15726*AL20*(1/(AB20*AO20^3))^(1/4) -> 0.0069315529 | BF20: =0.0019+0.0322*BE20-0.6642*BE20^2+4.9951*BE20^3 -> 0.0020929471 | BG20: =1-10.0147*BE20+33.8696*BE20^2+277.2817*BE20^3 -> 0.93230223 | BH20: =BF20/BG20 -> 0.0022449234 | BI20: =BB20*($K$18^0.1)*BH20 -> 0.035864305 | BJ20: =(BC20^0.575)*(14.7^0.1)*BD20 -> 342.40319 | BK20: =BI20/BJ20 -> 0.00010474291 | BL20: =(0.0047+1123.32*BK20+729489.64*BK20^2) -> 0.13036309 | BM20: =(1+1097.1566*BK20+722153.97*BK20^2) -> 1.1228422 | BN20: =SQRT(BL20/BM20) -> 0.34073595 | BO20: =(BC20*BE20^0.38)/BD20^2.14 -> 0.00054192547 | BP20: =1.0886-69.9473*BO20+2334.3497*BO20^2-12896.683*BO20^3 -> 1.0513773 | BQ20: =1-53.4401*BO20+1517.9369*BO20^2-8419.8115*BO20^3 -> 0.9714839 | BR20: =BP20/BQ20 -> 1.0822385 | BS20: =IF(U20<=0,1,(BN20*BR20)) -> 0.36875757 | BT20: =IF(U20>1,BN20*BR20,1) -> 0.36875757 | BU20: =IF($P$5=0,1,BT20) -> 0.36875757 | BV20: =AB20*AU20 -> 202.88694 | BW20: =EU20*AV20 -> 6.9132268 | BX20: =$T$10*(BV20+BW20)*86400 -> 1581859.7 | BY20: =(AL20^BS20)*EX20^(1-BS20) -> 0.078314599 | BZ20: =2.2*10^-2*BX20/BY20/$T$9 -> 1333119.8 | CA20: =$CB$15/3.7065 -> 0.00016187778 | CB20: =5.0452/BZ20 -> 3.7845061e-06 | CC20: =LOG(($CB$15^1.1098/2.8257)+(7.149/BZ20)^0.8981) -> -3.94885 | CD20: =-4*LOG(CA20-(CB20*CC20)) -> 15.009853 | CE20: =1/CD20^2 -> 0.0044386116 | CF20: =BS20*AB20+(1-BS20)*EU20 -> 18.866826 | CG20: =CE20*BX20^2/($T$9)^5/CF20 -> 1.4305088e+11 | CH20: =(1/144)*(CF20+(CG20/74130000000)) -> 0.14442052 | CI20: =CH20*$CI$14 -> 28.884105 | CJ20: =CJ19+200 -> 600 | CK20: =C20+CI20 -> 400.34707 | CS20: =K20/$CQ$18 -> 0.51458993 | CT20: 0.8 | CU20: =0.27*CS20/CT20/$CR$18 -> 0.095520756 | CV20: =($CU$12+$CW$12/$CR$18+$CY$12/$CR$18^3+$DA$12/$CR$18^4+$DC$12/$CR$18^5)*CU20 -> -0.033622479 | CW20: =($DE$12+$DG$12/$CR$18+$CU$13/$CR$18^2)*CU20^2 -> 0.0018104814 | CX20: =$CW$13*($DG$12/$CR$18+$CU$13/$CR$18^2)*CU20^5 -> -2.9313668e-07 | CY20: =$CY$13*(1+$DA$13*CU20^2)*(CU20^2/$CR$18^3) -> 0.00093729223 | CZ20: =EXP(-$DA$13*CU20^2) -> 0.99344303 | DA20: =1+CV20+CW20-CX20+CY20*CZ20 -> 0.96911944 | DB20: =DA20-CT20 -> 0.16911944 | DC20: 0.85 | DD20: =0.27*CS20/DC20/$CR$18 -> 0.089901888 | DE20: =($CU$12+$CW$12/$CR$18+$CY$12/$CR$18^3+$DA$12/$CR$18^4+$DC$12/$CR$18^5)*DD20 -> -0.031644686 | DF20: =($DE$12+$DG$12/$CR$18+$CU$13/$CR$18^2)*DD20^2 -> 0.0016037483 | DG20: =$CW$13*($DG$12/$CR$18+$CU$13/$CR$18^2)*DD20^5 -> -2.1648384e-07 | DH20: =$CY$13*(1+$DA$13*DD20^2)*DD20^2/$CR$18^3 -> 0.00082964617 | DI20: =EXP(-$DA$13*DD20^2) -> 0.99418957 | DJ20: =1+DE20+DF20-DG20+DH20*DI20 -> 0.9707841 | DK20: =DJ20-DC20 -> 0.1207841 | DL20: =(DK20-DB20)/(DC20-CT20) -> -0.96670676 | DM20: =CT20-DB20/DL20 -> 0.97494389 | DN20: =DC20 -> 0.85 | DO20: =0.27*CS20/DN20/$CR$18 -> 0.089901888 | DP20: =($CU$12+$CW$12/$CR$18+$CY$12/$CR$18^3+$DA$12/$CR$18^4+$DC$12/$CR$18^5)*DO20 -> -0.031644686 | DQ20: =($DE$12+$DG$12/$CR$18+$CU$13/$CR$18^2)*DO20^2 -> 0.0016037483 | DR20: =$CW$13*($DG$12/$CR$18+$CU$13/$CR$18^2)*DO20^5 -> -2.1648384e-07 | DS20: =$CY$13*(1+$DA$13*DO20^2)*(DO20^2/$CR$18^3) -> 0.00082964617 | DT20: =EXP(-$DA$13*DO20^2) -> 0.99418957 | DU20: =1+DP20+DQ20-DR20+DS20*DT20 -> 0.9707841 | DV20: =DU20-DN20 -> 0.1207841 | DW20: =DM20 -> 0.97494389 | DX20: =0.27*CS20/DW20/$CR$18 -> 0.078380515 | DY20: =($CU$12+$CW$12/$CR$18+$CY$12/$CR$18^3+$DA$12/$CR$18^4+$DC$12/$CR$18^5)*DX20 -> -0.027589263 | DZ20: =($DE$12+$DG$12/$CR$18+$CU$13/$CR$18^2)*DX20^2 -> 0.0012190312 | EA20: =$CW$13*($DG$12/$CR$18+$CU$13/$CR$18^2)*DX20^5 -> -1.0904908e-07 | EB20: =$CY$13*(1+$DA$13*DX20^2)*DX20^2/$CR$18^3 -> 0.00062974904 | EC20: =EXP(-$DA$13*DX20^2) -> 0.99558033 | ED20: =1+DY20+DZ20-EA20+EB20*EC20 -> 0.97425684 | EE20: =ED20-DW20 -> -0.00068704846 | EF20: =(EE20-DV20)/(DW20-DN20) -> -0.97220561 | EG20: =DN20-DV20/EF20 -> 0.9742372 | EK20: =K20 -> 343.23148 | EU20: =(EK20*$EO$18)/(DM20*10.73*$EJ$18) -> 0.90857485 | EV20: =EU20/67.0176 -> 0.013557257 | EW20: =EXP($ES$18*EV20^$ET$18) -> 1.0179355 | EX20: =$ER$18*10^-4*EW20 -> 0.013959501 | EZ20: 260.6 | FA20: 1509.8 | FC20: 491 | FD20: 1000.3
C21: =E20 -> 400.34707 | D21: 315.1 | E21: =CK21 -> 429.56417 | F21: =D21-E21 -> -114.46417 | G21: =AVERAGE(C21,D21) -> 357.72354 | I21: =Sheet10!K21 -> 418.39644 | K21: =G21 -> 357.72354 | O21: =(($P$8*K21^1.187)/56.06)*10^(10.393*$N$18) -> 41.951598 | Q21: =1+(4.67*10^-4*O21)+(0.11*10^-4*$P$18)+(0.1337*10^-8*O21*$P$18) -> 1.0993198 | R21: =0.0283*AS21*($M$18)/K21 -> 0.052354252 | S21: =$P$3*($P$4+Q21) -> 5496.5991 | T21: =S21*5.615 -> 30863.404 | U21: =IF($P$5>0,R21*($P$10-O21)*$P$3,0) -> 54461.092 | V21: =$X$14+$Y$13*(O21-$W$14) -> 0.88520553 | W21: =(8830/(131.5+$P$9)) -> 54.006116 | X21: =0.01361*V21*O21 -> 0.50541806 | Y21: =(W21+X21)/Q21 -> 49.586602 | Z21: =($P$4*$T$6)+(Q21*Y21) -> 54.511534 | AA21: =$P$4+Q21 -> 1.0993198 | AB21: =Z21/AA21 -> 49.586602 | AG21: =10.715*(O21+100)^-0.515 -> 0.83491051 | AH21: =5.44*(O21+150)^-0.338 -> 0.92019548 | AI21: =AG21*$AF$18^AH21 -> 1.4854575 | AJ21: =(($P$4*$T$6)/($P$4*$T$6+Q21*Y21))*$T$7 -> 0 | AK21: =((Q21*Y21)/($P$4*$T$6+Q21*Y21))*AI21 -> 1.4854575 | AL21: =AJ21+AK21 -> 1.4854575 | AM21: =(($P$4*$T$6)/($P$4*$T$6+Q21*Y21))*$T$8 -> 0 | AN21: =((Q21*Y21)/($P$4*$T$6+Q21*Y21))*$T$4 -> 30 | AO21: =AM21+AN21 -> 30 | AQ21: =CS21 -> 0.53631715 | AS21: =EG21 -> 0.97320454 | AU21: =(T21)*(1/86400)/$T$10 -> 4.0933765 | AV21: =(U21)*(1/86400)/$T$10 -> 7.2231098 | AW21: =AU21+AV21 -> 11.316486 | AX21: =AU21/AW21 -> 0.36171797 | AY21: =1-AX21 -> 0.63828203 | AZ21: =1.071-(0.2218*((AW21^2)/($T$9))) -> -84.142029 | BA21: =IF(AZ21<0.13,0.13,AZ21) -> 0.13 | BB21: =1.938*AU21*(AB21/AO21)^(1/4) -> 8.9948979 | BC21: =1.938*AV21*(AB21/AO21)^(1/4) -> 15.87226 | BD21: =120.872*$T$9*SQRT(AB21/AO21) -> 51.799552 | BE21: =0.15726*AL21*(1/(AB21*AO21^3))^(1/4) -> 0.0068674653 | BF21: =0.0019+0.0322*BE21-0.6642*BE21^2+4.9951*BE21^3 -> 0.0020914252 | BG21: =1-10.0147*BE21+33.8696*BE21^2+277.2817*BE21^3 -> 0.93291156 | BH21: =BF21/BG21 -> 0.0022418257 | BI21: =BB21*($K$18^0.1)*BH21 -> 0.0358422 | BJ21: =(BC21^0.575)*(14.7^0.1)*BD21 -> 332.21943 | BK21: =BI21/BJ21 -> 0.00010788713 | BL21: =(0.0047+1123.32*BK21+729489.64*BK21^2) -> 0.13438276 | BM21: =(1+1097.1566*BK21+722153.97*BK21^2) -> 1.1267747 | BN21: =SQRT(BL21/BM21) -> 0.34534506 | BO21: =(BC21*BE21^0.38)/BD21^2.14 -> 0.00051281862 | BP21: =1.0886-69.9473*BO21+2334.3497*BO21^2-12896.683*BO21^3 -> 1.0533419 | BQ21: =1-53.4401*BO21+1517.9369*BO21^2-8419.8115*BO21^3 -> 0.97299298 | BR21: =BP21/BQ21 -> 1.0825791 | BS21: =IF(U21<=0,1,(BN21*BR21)) -> 0.37386334 | BT21: =IF(U21>1,BN21*BR21,1) -> 0.37386334 | BU21: =IF($P$5=0,1,BT21) -> 0.37386334 | BV21: =AB21*AU21 -> 202.97663 | BW21: =EU21*AV21 -> 6.846998 | BX21: =$T$10*(BV21+BW21)*86400 -> 1582036.6 | BY21: =(AL21^BS21)*EX21^(1-BS21) -> 0.079976896 | BZ21: =2.2*10^-2*BX21/BY21/$T$9 -> 1305557.2 | CA21: =$CB$15/3.7065 -> 0.00016187778 | CB21: =5.0452/BZ21 -> 3.8644036e-06 | CC21: =LOG(($CB$15^1.1098/2.8257)+(7.149/BZ21)^0.8981) -> -3.9475017 | CD21: =-4*LOG(CA21-(CB21*CC21)) -> 15.006807 | CE21: =1/CD21^2 -> 0.0044404135 | CF21: =BS21*AB21+(1-BS21)*EU21 -> 19.132146 | CG21: =CE21*BX21^2/($T$9)^5/CF21 -> 1.411559e+11 | CH21: =(1/144)*(CF21+(CG21/74130000000)) -> 0.14608551 | CI21: =CH21*$CI$14 -> 29.217102 | CJ21: =CJ20+200 -> 800 | CK21: =C21+CI21 -> 429.56417 | CS21: =K21/$CQ$18 -> 0.53631715 | CT21: 0.8 | CU21: =0.27*CS21/CT21/$CR$18 -> 0.09955387 | CV21: =($CU$12+$CW$12/$CR$18+$CY$12/$CR$18^3+$DA$12/$CR$18^4+$DC$12/$CR$18^5)*CU21 -> -0.0350421 | CW21: =($DE$12+$DG$12/$CR$18+$CU$13/$CR$18^2)*CU21^2 -> 0.0019665947 | CX21: =$CW$13*($DG$12/$CR$18+$CU$13/$CR$18^2)*CU21^5 -> -3.6047252e-07 | CY21: =$CY$13*(1+$DA$13*CU21^2)*(CU21^2/$CR$18^3) -> 0.0010186863 | CZ21: =EXP(-$DA$13*CU21^2) -> 0.99287966 | DA21: =1+CV21+CW21-CX21+CY21*CZ21 -> 0.96793629 | DB21: =DA21-CT21 -> 0.16793629 | DC21: 0.85 | DD21: =0.27*CS21/DC21/$CR$18 -> 0.09369776 | DE21: =($CU$12+$CW$12/$CR$18+$CY$12/$CR$18^3+$DA$12/$CR$18^4+$DC$12/$CR$18^5)*DD21 -> -0.0329808 | DF21: =($DE$12+$DG$12/$CR$18+$CU$13/$CR$18^2)*DD21^2 -> 0.0017420355 | DG21: =$CW$13*($DG$12/$CR$18+$CU$13/$CR$18^2)*DD21^5 -> -2.662119e-07 | DH21: =$CY$13*(1+$DA$13*DD21^2)*DD21^2/$CR$18^3 -> 0.00090163469 | DI21: =EXP(-$DA$13*DD21^2) -> 0.99369014 | DJ21: =1+DE21+DF21-DG21+DH21*DI21 -> 0.96965745 | DK21: =DJ21-DC21 -> 0.11965745 | DL21: =(DK21-DB21)/(DC21-CT21) -> -0.96557682 | DM21: =CT21-DB21/DL21 -> 0.97392328 | DN21: =DC21 -> 0.85 | DO21: =0.27*CS21/DN21/$CR$18 -> 0.09369776 | DP21: =($CU$12+$CW$12/$CR$18+$CY$12/$CR$18^3+$DA$12/$CR$18^4+$DC$12/$CR$18^5)*DO21 -> -0.0329808 | DQ21: =($DE$12+$DG$12/$CR$18+$CU$13/$CR$18^2)*DO21^2 -> 0.0017420355 | DR21: =$CW$13*($DG$12/$CR$18+$CU$13/$CR$18^2)*DO21^5 -> -2.662119e-07 | DS21: =$CY$13*(1+$DA$13*DO21^2)*(DO21^2/$CR$18^3) -> 0.00090163469 | DT21: =EXP(-$DA$13*DO21^2) -> 0.99369014 | DU21: =1+DP21+DQ21-DR21+DS21*DT21 -> 0.96965745 | DV21: =DU21-DN21 -> 0.11965745 | DW21: =DM21 -> 0.97392328 | DX21: =0.27*CS21/DW21/$CR$18 -> 0.081775534 | DY21: =($CU$12+$CW$12/$CR$18+$CY$12/$CR$18^3+$DA$12/$CR$18^4+$DC$12/$CR$18^5)*DX21 -> -0.02878428 | DZ21: =($DE$12+$DG$12/$CR$18+$CU$13/$CR$18^2)*DX21^2 -> 0.0013269219 | EA21: =$CW$13*($DG$12/$CR$18+$CU$13/$CR$18^2)*DX21^5 -> -1.3480263e-07 | EB21: =$CY$13*(1+$DA$13*DX21^2)*DX21^2/$CR$18^3 -> 0.00068575271 | EC21: =EXP(-$DA$13*DX21^2) -> 0.99519011 | ED21: =1+DY21+DZ21-EA21+EB21*EC21 -> 0.97322523 | EE21: =ED21-DW21 -> -0.00069804926 | EF21: =(EE21-DV21)/(DW21-DN21) -> -0.97120973 | EG21: =DN21-DV21/EF21 -> 0.97320454 | EK21: =K21 -> 357.72354 | EU21: =(EK21*$EO$18)/(DM21*10.73*$EJ$18) -> 0.94792938 | EV21: =EU21/67.0176 -> 0.014144484 | EW21: =EXP($ES$18*EV21^$ET$18) -> 1.0189739 | EX21: =$ER$18*10^-4*EW21 -> 0.013973742 | EZ21: 355.1 | FA21: 2140.4 | FC21: 802 | FD21: 1750.1
C22: =E21 -> 429.56417 | D22: 315.2 | E22: =CK22 -> 459.11307 | F22: =D22-E22 -> -143.91307 | G22: =AVERAGE(C22,D22) -> 372.38209 | I22: =Sheet10!K22 -> 449.65759 | K22: =G22 -> 372.38209 | O22: =(($P$8*K22^1.187)/56.06)*10^(10.393*$N$18) -> 43.99986 | Q22: =1+(4.67*10^-4*O22)+(0.11*10^-4*$P$18)+(0.1337*10^-8*O22*$P$18) -> 1.1002961 | R22: =0.0283*AS22*($M$18)/K22 -> 0.050239644 | S22: =$P$3*($P$4+Q22) -> 5501.4805 | T22: =S22*5.615 -> 30890.813 | U22: =IF($P$5>0,R22*($P$10-O22)*$P$3,0) -> 51746.868 | V22: =$X$14+$Y$13*(O22-$W$14) -> 0.88497144 | W22: =(8830/(131.5+$P$9)) -> 54.006116 | X22: =0.01361*V22*O22 -> 0.52995461 | Y22: =(W22+X22)/Q22 -> 49.564904 | Z22: =($P$4*$T$6)+(Q22*Y22) -> 54.536071 | AA22: =$P$4+Q22 -> 1.1002961 | AB22: =Z22/AA22 -> 49.564904 | AG22: =10.715*(O22+100)^-0.515 -> 0.82877322 | AH22: =5.44*(O22+150)^-0.338 -> 0.9169001 | AI22: =AG22*$AF$18^AH22 -> 1.4714989 | AJ22: =(($P$4*$T$6)/($P$4*$T$6+Q22*Y22))*$T$7 -> 0 | AK22: =((Q22*Y22)/($P$4*$T$6+Q22*Y22))*AI22 -> 1.4714989 | AL22: =AJ22+AK22 -> 1.4714989 | AM22: =(($P$4*$T$6)/($P$4*$T$6+Q22*Y22))*$T$8 -> 0 | AN22: =((Q22*Y22)/($P$4*$T$6+Q22*Y22))*$T$4 -> 30 | AO22: =AM22+AN22 -> 30 | AQ22: =CS22 -> 0.55829398 | AS22: =EG22 -> 0.97216501 | AU22: =(T22)*(1/86400)/$T$10 -> 4.0970117 | AV22: =(U22)*(1/86400)/$T$10 -> 6.8631255 | AW22: =AU22+AV22 -> 10.960137 | AX22: =AU22/AW22 -> 0.37381026 | AY22: =1-AX22 -> 0.62618974 | AZ22: =1.071-(0.2218*((AW22^2)/($T$9))) -> -78.859915 | BA22: =IF(AZ22<0.13,0.13,AZ22) -> 0.13 | BB22: =1.938*AU22*(AB22/AO22)^(1/4) -> 9.0019011 | BC22: =1.938*AV22*(AB22/AO22)^(1/4) -> 15.07957 | BD22: =120.872*$T$9*SQRT(AB22/AO22) -> 51.788217 | BE22: =0.15726*AL22*(1/(AB22*AO22^3))^(1/4) -> 0.0068036771 | BF22: =0.0019+0.0322*BE22-0.6642*BE22^2+4.9951*BE22^3 -> 0.0020899057 | BG22: =1-10.0147*BE22+33.8696*BE22^2+277.2817*BE22^3 -> 0.93351837 | BH22: =BF22/BG22 -> 0.0022387409 | BI22: =BB22*($K$18^0.1)*BH22 -> 0.035820747 | BJ22: =(BC22^0.575)*(14.7^0.1)*BD22 -> 322.50493 | BK22: =BI22/BJ22 -> 0.00011107039 | BL22: =(0.0047+1123.32*BK22+729489.64*BK22^2) -> 0.13846703 | BM22: =(1+1097.1566*BK22+722153.97*BK22^2) -> 1.1307706 | BN22: =SQRT(BL22/BM22) -> 0.34993384 | BO22: =(BC22*BE22^0.38)/BD22^2.14 -> 0.0004857103 | BP22: =1.0886-69.9473*BO22+2334.3497*BO22^2-12896.683*BO22^3 -> 1.0551751 | BQ22: =1-53.4401*BO22+1517.9369*BO22^2-8419.8115*BO22^3 -> 0.97440073 | BR22: =BP22/BQ22 -> 1.0828965 | BS22: =IF(U22<=0,1,(BN22*BR22)) -> 0.37894212 | BT22: =IF(U22>1,BN22*BR22,1) -> 0.37894212 | BU22: =IF($P$5=0,1,BT22) -> 0.37894212 | BV22: =AB22*AU22 -> 203.06799 | BW22: =EU22*AV22 -> 6.7795065 | BX22: =$T$10*(BV22+BW22)*86400 -> 1582216.6 | BY22: =(AL22^BS22)*EX22^(1-BS22) -> 0.081655526 | BZ22: =2.2*10^-2*BX22/BY22/$T$9 -> 1278863.8 | CA22: =$CB$15/3.7065 -> 0.00016187778 | CB22: =5.0452/BZ22 -> 3.9450644e-06 | CC22: =LOG(($CB$15^1.1098/2.8257)+(7.149/BZ22)^0.8981) -> -3.9461475 | CD22: =-4*LOG(CA22-(CB22*CC22)) -> 15.003739 | CE22: =1/CD22^2 -> 0.0044422295 | CF22: =BS22*AB22+(1-BS22)*EU22 -> 19.395721 | CG22: =CE22*BX22^2/($T$9)^5/CF22 -> 1.3932633e+11 | CH22: =(1/144)*(CF22+(CG22/74130000000)) -> 0.1477445 | CI22: =CH22*$CI$14 -> 29.548899 | CJ22: =CJ21+200 -> 1000 | CK22: =C22+CI22 -> 459.11307 | CS22: =K22/$CQ$18 -> 0.55829398 | CT22: 0.8 | CU22: =0.27*CS22/CT22/$CR$18 -> 0.10363332 | CV22: =($CU$12+$CW$12/$CR$18+$CY$12/$CR$18^3+$DA$12/$CR$18^4+$DC$12/$CR$18^5)*CU22 -> -0.036478032 | CW22: =($DE$12+$DG$12/$CR$18+$CU$13/$CR$18^2)*CU22^2 -> 0.0021310685 | CX22: =$CW$13*($DG$12/$CR$18+$CU$13/$CR$18^2)*CU22^5 -> -4.4063449e-07 | CY22: =$CY$13*(1+$DA$13*CU22^2)*(CU22^2/$CR$18^3) -> 0.001104538 | CZ22: =EXP(-$DA$13*CU22^2) -> 0.99228646 | DA22: =1+CV22+CW22-CX22+CY22*CZ22 -> 0.9667495 | DB22: =DA22-CT22 -> 0.1667495 | DC22: 0.85 | DD22: =0.27*CS22/DC22/$CR$18 -> 0.097537243 | DE22: =($CU$12+$CW$12/$CR$18+$CY$12/$CR$18^3+$DA$12/$CR$18^4+$DC$12/$CR$18^5)*DD22 -> -0.034332265 | DF22: =($DE$12+$DG$12/$CR$18+$CU$13/$CR$18^2)*DD22^2 -> 0.0018877285 | DG22: =$CW$13*($DG$12/$CR$18+$CU$13/$CR$18^2)*DD22^5 -> -3.2541217e-07 | DH22: =$CY$13*(1+$DA$13*DD22^2)*DD22^2/$CR$18^3 -> 0.00097755579 | DI22: =EXP(-$DA$13*DD22^2) -> 0.99316423 | DJ22: =1+DE22+DF22-DG22+DH22*DI22 -> 0.96852666 | DK22: =DJ22-DC22 -> 0.11852666 | DL22: =(DK22-DB22)/(DC22-CT22) -> -0.96445667 | DM22: =CT22-DB22/DL22 -> 0.97289475 | DN22: =DC22 -> 0.85 | DO22: =0.27*CS22/DN22/$CR$18 -> 0.097537243 | DP22: =($CU$12+$CW$12/$CR$18+$CY$12/$CR$18^3+$DA$12/$CR$18^4+$DC$12/$CR$18^5)*DO22 -> -0.034332265 | DQ22: =($DE$12+$DG$12/$CR$18+$CU$13/$CR$18^2)*DO22^2 -> 0.0018877285 | DR22: =$CW$13*($DG$12/$CR$18+$CU$13/$CR$18^2)*DO22^5 -> -3.2541217e-07 | DS22: =$CY$13*(1+$DA$13*DO22^2)*(DO22^2/$CR$18^3) -> 0.00097755579 | DT22: =EXP(-$DA$13*DO22^2) -> 0.99316423 | DU22: =1+DP22+DQ22-DR22+DS22*DT22 -> 0.96852666 | DV22: =DU22-DN22 -> 0.11852666 | DW22: =DM22 -> 0.97289475 | DX22: =0.27*CS22/DW22/$CR$18 -> 0.08521647 | DY22: =($CU$12+$CW$12/$CR$18+$CY$12/$CR$18^3+$DA$12/$CR$18^4+$DC$12/$CR$18^5)*DX22 -> -0.02999546 | DZ22: =($DE$12+$DG$12/$CR$18+$CU$13/$CR$18^2)*DX22^2 -> 0.0014409392 | EA22: =$CW$13*($DG$12/$CR$18+$CU$13/$CR$18^2)*DX22^5 -> -1.6565293e-07 | EB22: =$CY$13*(1+$DA$13*DX22^2)*DX22^2/$CR$18^3 -> 0.00074498386 | EC22: =EXP(-$DA$13*DX22^2) -> 0.99477789 | ED22: =1+DY22+DZ22-EA22+EB22*EC22 -> 0.97218674 | EE22: =ED22-DW22 -> -0.00070801286 | EF22: =(EE22-DV22)/(DW22-DN22) -> -0.9702178 | EG22: =DN22-DV22/EF22 -> 0.97216501 | EK22: =K22 -> 372.38209 | EU22: =(EK22*$EO$18)/(DM22*10.73*$EJ$18) -> 0.98781619 | EV22: =EU22/67.0176 -> 0.014739653 | EW22: =EXP($ES$18*EV22^$ET$18) -> 1.0200414 | EX22: =$ER$18*10^-4*EW22 -> 0.013988381 | EZ22: 472.9 | FA22: 3019.3 | FC22: 1124.9 | FD22: 2538.3
C23: =E22 -> 459.11307 | D23: 315.3 | E23: =CK23 -> 488.99285 | F23: =D23-E23 -> -173.69285 | G23: =AVERAGE(C23,D23) -> 387.20654 | I23: =Sheet10!K23 -> 481.58323 | K23: =G23 -> 387.20654 | O23: =(($P$8*K23^1.187)/56.06)*10^(10.393*$N$18) -> 46.086695 | Q23: =1+(4.67*10^-4*O23)+(0.11*10^-4*$P$18)+(0.1337*10^-8*O23*$P$18) -> 1.1012908 | R23: =0.0283*AS23*($M$18)/K23 -> 0.048264194 | S23: =$P$3*($P$4+Q23) -> 5506.4539 | T23: =S23*5.615 -> 30918.738 | U23: =IF($P$5>0,R23*($P$10-O23)*$P$3,0) -> 49208.557 | V23: =$X$14+$Y$13*(O23-$W$14) -> 0.88473295 | W23: =(8830/(131.5+$P$9)) -> 54.006116 | X23: =0.01361*V23*O23 -> 0.55493983 | Y23: =(W23+X23)/Q23 -> 49.542825 | Z23: =($P$4*$T$6)+(Q23*Y23) -> 54.561056 | AA23: =$P$4+Q23 -> 1.1012908 | AB23: =Z23/AA23 -> 49.542825 | AG23: =10.715*(O23+100)^-0.515 -> 0.82265489 | AH23: =5.44*(O23+150)^-0.338 -> 0.9135902 | AI23: =AG23*$AF$18^AH23 -> 1.4576118 | AJ23: =(($P$4*$T$6)/($P$4*$T$6+Q23*Y23))*$T$7 -> 0 | AK23: =((Q23*Y23)/($P$4*$T$6+Q23*Y23))*AI23 -> 1.4576118 | AL23: =AJ23+AK23 -> 1.4576118 | AM23: =(($P$4*$T$6)/($P$4*$T$6+Q23*Y23))*$T$8 -> 0 | AN23: =((Q23*Y23)/($P$4*$T$6+Q23*Y23))*$T$4 -> 30 | AO23: =AM23+AN23 -> 30 | AQ23: =CS23 -> 0.58051954 | AS23: =EG23 -> 0.97111887 | AU23: =(T23)*(1/86400)/$T$10 -> 4.1007155 | AV23: =(U23)*(1/86400)/$T$10 -> 6.5264723 | AW23: =AU23+AV23 -> 10.627188 | AX23: =AU23/AW23 -> 0.38587024 | AY23: =1-AX23 -> 0.61412976 | AZ23: =1.071-(0.2218*((AW23^2)/($T$9))) -> -74.077359 | BA23: =IF(AZ23<0.13,0.13,AZ23) -> 0.13 | BB23: =1.938*AU23*(AB23/AO23)^(1/4) -> 9.0090353 | BC23: =1.938*AV23*(AB23/AO23)^(1/4) -> 14.338283 | BD23: =120.872*$T$9*SQRT(AB23/AO23) -> 51.776681 | BE23: =0.15726*AL23*(1/(AB23*AO23^3))^(1/4) -> 0.0067402191 | BF23: =0.0019+0.0322*BE23-0.6642*BE23^2+4.9951*BE23^3 -> 0.0020883896 | BG23: =1-10.0147*BE23+33.8696*BE23^2+277.2817*BE23^3 -> 0.93412235 | BH23: =BF23/BG23 -> 0.0022356703 | BI23: =BB23*($K$18^0.1)*BH23 -> 0.035799967 | BJ23: =(BC23^0.575)*(14.7^0.1)*BD23 -> 313.22167 | BK23: =BI23/BJ23 -> 0.00011429595 | BL23: =(0.0047+1123.32*BK23+729489.64*BK23^2) -> 0.14262066 | BM23: =(1+1097.1566*BK23+722153.97*BK23^2) -> 1.1348345 | BN23: =SQRT(BL23/BM23) -> 0.35450712 | BO23: =(BC23*BE23^0.38)/BD23^2.14 -> 0.0004604114 | BP23: =1.0886-69.9473*BO23+2334.3497*BO23^2-12896.683*BO23^3 -> 1.056889 | BQ23: =1-53.4401*BO23+1517.9369*BO23^2-8419.8115*BO23^3 -> 0.97571652 | BR23: =BP23/BQ23 -> 1.0831927 | BS23: =IF(U23<=0,1,(BN23*BR23)) -> 0.38399953 | BT23: =IF(U23>1,BN23*BR23,1) -> 0.38399953 | BU23: =IF($P$5=0,1,BT23) -> 0.38399953 | BV23: =AB23*AU23 -> 203.16103 | BW23: =EU23*AV23 -> 6.7107542 | BX23: =$T$10*(BV23+BW23)*86400 -> 1582399.7 | BY23: =(AL23^BS23)*EX23^(1-BS23) -> 0.083352345 | BZ23: =2.2*10^-2*BX23/BY23/$T$9 -> 1252974.7 | CA23: =$CB$15/3.7065 -> 0.00016187778 | CB23: =5.0452/BZ23 -> 4.0265778e-06 | CC23: =LOG(($CB$15^1.1098/2.8257)+(7.149/BZ23)^0.8981) -> -3.9447862 | CD23: =-4*LOG(CA23-(CB23*CC23)) -> 15.000647 | CE23: =1/CD23^2 -> 0.0044440613 | CF23: =BS23*AB23+(1-BS23)*EU23 -> 19.657815 | CG23: =CE23*BX23^2/($T$9)^5/CF23 -> 1.3755723e+11 | CH23: =(1/144)*(CF23+(CG23/74130000000)) -> 0.14939887 | CI23: =CH23*$CI$14 -> 29.879774 | CJ23: =CJ22+200 -> 1200 | CK23: =C23+CI23 -> 488.99285 | CS23: =K23/$CQ$18 -> 0.58051954 | CT23: 0.8 | CU23: =0.27*CS23/CT23/$CR$18 -> 0.10775894 | CV23: =($CU$12+$CW$12/$CR$18+$CY$12/$CR$18^3+$DA$12/$CR$18^4+$DC$12/$CR$18^5)*CU23 -> -0.037930214 | CW23: =($DE$12+$DG$12/$CR$18+$CU$13/$CR$18^2)*CU23^2 -> 0.0023041206 | CX23: =$CW$13*($DG$12/$CR$18+$CU$13/$CR$18^2)*CU23^5 -> -5.3560915e-07 | CY23: =$CY$13*(1+$DA$13*CU23^2)*(CU23^2/$CR$18^3) -> 0.0011949765 | CZ23: =EXP(-$DA$13*CU23^2) -> 0.99166271 | DA23: =1+CV23+CW23-CX23+CY23*CZ23 -> 0.96555946 | DB23: =DA23-CT23 -> 0.16555946 | DC23: 0.85 | DD23: =0.27*CS23/DC23/$CR$18 -> 0.10142018 | DE23: =($CU$12+$CW$12/$CR$18+$CY$12/$CR$18^3+$DA$12/$CR$18^4+$DC$12/$CR$18^5)*DD23 -> -0.035699025 | DF23: =($DE$12+$DG$12/$CR$18+$CU$13/$CR$18^2)*DD23^2 -> 0.0020410203 | DG23: =$CW$13*($DG$12/$CR$18+$CU$13/$CR$18^2)*DD23^5 -> -3.9555173e-07 | DH23: =$CY$13*(1+$DA$13*DD23^2)*DD23^2/$CR$18^3 -> 0.0010575223 | DI23: =EXP(-$DA$13*DD23^2) -> 0.99261119 | DJ23: =1+DE23+DF23-DG23+DH23*DI23 -> 0.9673921 | DK23: =DJ23-DC23 -> 0.1173921 | DL23: =(DK23-DB23)/(DC23-CT23) -> -0.96334713 | DM23: =CT23-DB23/DL23 -> 0.97185857 | DN23: =DC23 -> 0.85 | DO23: =0.27*CS23/DN23/$CR$18 -> 0.10142018 | DP23: =($CU$12+$CW$12/$CR$18+$CY$12/$CR$18^3+$DA$12/$CR$18^4+$DC$12/$CR$18^5)*DO23 -> -0.035699025 | DQ23: =($DE$12+$DG$12/$CR$18+$CU$13/$CR$18^2)*DO23^2 -> 0.0020410203 | DR23: =$CW$13*($DG$12/$CR$18+$CU$13/$CR$18^2)*DO23^5 -> -3.9555173e-07 | DS23: =$CY$13*(1+$DA$13*DO23^2)*(DO23^2/$CR$18^3) -> 0.0010575223 | DT23: =EXP(-$DA$13*DO23^2) -> 0.99261119 | DU23: =1+DP23+DQ23-DR23+DS23*DT23 -> 0.9673921 | DV23: =DU23-DN23 -> 0.1173921 | DW23: =DM23 -> 0.97185857 | DX23: =0.27*CS23/DW23/$CR$18 -> 0.088703393 | DY23: =($CU$12+$CW$12/$CR$18+$CY$12/$CR$18^3+$DA$12/$CR$18^4+$DC$12/$CR$18^5)*DX23 -> -0.031222826 | DZ23: =($DE$12+$DG$12/$CR$18+$CU$13/$CR$18^2)*DX23^2 -> 0.0015612737 | EA23: =$CW$13*($DG$12/$CR$18+$CU$13/$CR$18^2)*DX23^5 -> -2.0243359e-07 | EB23: =$CY$13*(1+$DA$13*DX23^2)*DX23^2/$CR$18^3 -> 0.00080754943 | EC23: =EXP(-$DA$13*DX23^2) -> 0.99434302 | ED23: =1+DY23+DZ23-EA23+EB23*EC23 -> 0.97114163 | EE23: =ED23-DW23 -> -0.0007169349 | EF23: =(EE23-DV23)/(DW23-DN23) -> -0.96923046 | EG23: =DN23-DV23/EF23 -> 0.97111887 | EK23: =K23 -> 387.20654 | EU23: =(EK23*$EO$18)/(DM23*10.73*$EJ$18) -> 1.0282361 | EV23: =EU23/67.0176 -> 0.015342777 | EW23: =EXP($ES$18*EV23^$ET$18) -> 1.0211383 | EX23: =$ER$18*10^-4*EW23 -> 0.014003424 | EZ23: 591.2 | FA23: 3745.5 | FC23: 1603.3 | FD23: 3672.7
C24: =E23 -> 488.99285 | D24: 315.4 | E24: =CK24 -> 519.20284 | F24: =D24-E24 -> -203.80284 | G24: =AVERAGE(C24,D24) -> 402.19642 | I24: =Sheet10!K24 -> 514.17669 | K24: =G24 -> 402.19642 | O24: =(($P$8*K24^1.187)/56.06)*10^(10.393*$N$18) -> 48.212068 | Q24: =1+(4.67*10^-4*O24)+(0.11*10^-4*$P$18)+(0.1337*10^-8*O24*$P$18) -> 1.1023038 | R24: =0.0283*AS24*($M$18)/K24 -> 0.046415027 | S24: =$P$3*($P$4+Q24) -> 5511.5191 | T24: =S24*5.615 -> 30947.18 | U24: =IF($P$5>0,R24*($P$10-O24)*$P$3,0) -> 46829.962 | V24: =$X$14+$Y$13*(O24-$W$14) -> 0.88449005 | W24: =(8830/(131.5+$P$9)) -> 54.006116 | X24: =0.01361*V24*O24 -> 0.58037251 | Y24: =(W24+X24)/Q24 -> 49.520366 | Z24: =($P$4*$T$6)+(Q24*Y24) -> 54.586489 | AA24: =$P$4+Q24 -> 1.1023038 | AB24: =Z24/AA24 -> 49.520366 | AG24: =10.715*(O24+100)^-0.515 -> 0.81655819 | AH24: =5.44*(O24+150)^-0.338 -> 0.91026727 | AI24: =AG24*$AF$18^AH24 -> 1.4438024 | AJ24: =(($P$4*$T$6)/($P$4*$T$6+Q24*Y24))*$T$7 -> 0 | AK24: =((Q24*Y24)/($P$4*$T$6+Q24*Y24))*AI24 -> 1.4438024 | AL24: =AJ24+AK24 -> 1.4438024 | AM24: =(($P$4*$T$6)/($P$4*$T$6+Q24*Y24))*$T$8 -> 0 | AN24: =((Q24*Y24)/($P$4*$T$6+Q24*Y24))*$T$4 -> 30 | AO24: =AM24+AN24 -> 30 | AQ24: =CS24 -> 0.60299314 | AS24: =EG24 -> 0.9700664 | AU24: =(T24)*(1/86400)/$T$10 -> 4.1044876 | AV24: =(U24)*(1/86400)/$T$10 -> 6.211002 | AW24: =AU24+AV24 -> 10.31549 | AX24: =AU24/AW24 -> 0.39789557 | AY24: =1-AX24 -> 0.60210443 | AZ24: =1.071-(0.2218*((AW24^2)/($T$9))) -> -69.733765 | BA24: =IF(AZ24<0.13,0.13,AZ24) -> 0.13 | BB24: =1.938*AU24*(AB24/AO24)^(1/4) -> 9.0163003 | BC24: =1.938*AV24*(AB24/AO24)^(1/4) -> 13.643666 | BD24: =120.872*$T$9*SQRT(AB24/AO24) -> 51.764944 | BE24: =0.15726*AL24*(1/(AB24*AO24^3))^(1/4) -> 0.0066771191 | BF24: =0.0019+0.0322*BE24-0.6642*BE24^2+4.9951*BE24^3 -> 0.0020868776 | BG24: =1-10.0147*BE24+33.8696*BE24^2+277.2817*BE24^3 -> 0.93472324 | BH24: =BF24/BG24 -> 0.0022326155 | BI24: =BB24*($K$18^0.1)*BH24 -> 0.03577988 | BJ24: =(BC24^0.575)*(14.7^0.1)*BD24 -> 304.33567 | BK24: =BI24/BJ24 -> 0.00011756716 | BL24: =(0.0047+1123.32*BK24+729489.64*BK24^2) -> 0.14684857 | BM24: =(1+1097.1566*BK24+722153.97*BK24^2) -> 1.1389712 | BN24: =SQRT(BL24/BM24) -> 0.35906948 | BO24: =(BC24*BE24^0.38)/BD24^2.14 -> 0.00043675557 | BP24: =1.0886-69.9473*BO24+2334.3497*BO24^2-12896.683*BO24^3 -> 1.0584943 | BQ24: =1-53.4401*BO24+1517.9369*BO24^2-8419.8115*BO24^3 -> 0.97694859 | BR24: =BP24/BQ24 -> 1.0834698 | BS24: =IF(U24<=0,1,(BN24*BR24)) -> 0.38904095 | BT24: =IF(U24>1,BN24*BR24,1) -> 0.38904095 | BU24: =IF($P$5=0,1,BT24) -> 0.38904095 | BV24: =AB24*AU24 -> 203.25573 | BW24: =EU24*AV24 -> 6.6407422 | BX24: =$T$10*(BV24+BW24)*86400 -> 1582585.8 | BY24: =(AL24^BS24)*EX24^(1-BS24) -> 0.08506926 | BZ24: =2.2*10^-2*BX24/BY24/$T$9 -> 1227830.9 | CA24: =$CB$15/3.7065 -> 0.00016187778 | CB24: =5.0452/BZ24 -> 4.109035e-06 | CC24: =LOG(($CB$15^1.1098/2.8257)+(7.149/BZ24)^0.8981) -> -3.9434163 | CD24: =-4*LOG(CA24-(CB24*CC24)) -> 14.997526 | CE24: =1/CD24^2 -> 0.0044459111 | CF24: =BS24*AB24+(1-BS24)*EU24 -> 19.918682 | CG24: =CE24*BX24^2/($T$9)^5/CF24 -> 1.3584417e+11 | CH24: =(1/144)*(CF24+(CG24/74130000000)) -> 0.15104996 | CI24: =CH24*$CI$14 -> 30.209992 | CJ24: =CJ23+200 -> 1400 | CK24: =C24+CI24 -> 519.20284 | CS24: =K24/$CQ$18 -> 0.60299314 | CT24: 0.8 | CU24: =0.27*CS24/CT24/$CR$18 -> 0.1119306 | CV24: =($CU$12+$CW$12/$CR$18+$CY$12/$CR$18^3+$DA$12/$CR$18^4+$DC$12/$CR$18^5)*CU24 -> -0.039398603 | CW24: =($DE$12+$DG$12/$CR$18+$CU$13/$CR$18^2)*CU24^2 -> 0.0024859721 | CX24: =$CW$13*($DG$12/$CR$18+$CU$13/$CR$18^2)*CU24^5 -> -6.4762798e-07 | CY24: =$CY$13*(1+$DA$13*CU24^2)*(CU24^2/$CR$18^3) -> 0.0012901342 | CZ24: =EXP(-$DA$13*CU24^2) -> 0.99100766 | DA24: =1+CV24+CW24-CX24+CY24*CZ24 -> 0.96436655 | DB24: =DA24-CT24 -> 0.16436655 | DC24: 0.85 | DD24: =0.27*CS24/DC24/$CR$18 -> 0.10534645 | DE24: =($CU$12+$CW$12/$CR$18+$CY$12/$CR$18^3+$DA$12/$CR$18^4+$DC$12/$CR$18^5)*DD24 -> -0.037081038 | DF24: =($DE$12+$DG$12/$CR$18+$CU$13/$CR$18^2)*DD24^2 -> 0.0022021068 | DG24: =$CW$13*($DG$12/$CR$18+$CU$13/$CR$18^2)*DD24^5 -> -4.7827856e-07 | DH24: =$CY$13*(1+$DA$13*DD24^2)*DD24^2/$CR$18^3 -> 0.0011416496 | DI24: =EXP(-$DA$13*DD24^2) -> 0.99203036 | DJ24: =1+DE24+DF24-DG24+DH24*DI24 -> 0.9662541 | DK24: =DJ24-DC24 -> 0.1162541 | DL24: =(DK24-DB24)/(DC24-CT24) -> -0.96224903 | DM24: =CT24-DB24/DL24 -> 0.97081498 | DN24: =DC24 -> 0.85 | DO24: =0.27*CS24/DN24/$CR$18 -> 0.10534645 | DP24: =($CU$12+$CW$12/$CR$18+$CY$12/$CR$18^3+$DA$12/$CR$18^4+$DC$12/$CR$18^5)*DO24 -> -0.037081038 | DQ24: =($DE$12+$DG$12/$CR$18+$CU$13/$CR$18^2)*DO24^2 -> 0.0022021068 | DR24: =$CW$13*($DG$12/$CR$18+$CU$13/$CR$18^2)*DO24^5 -> -4.7827856e-07 | DS24: =$CY$13*(1+$DA$13*DO24^2)*(DO24^2/$CR$18^3) -> 0.0011416496 | DT24: =EXP(-$DA$13*DO24^2) -> 0.99203036 | DU24: =1+DP24+DQ24-DR24+DS24*DT24 -> 0.9662541 | DV24: =DU24-DN24 -> 0.1162541 | DW24: =DM24 -> 0.97081498 | DX24: =0.27*CS24/DW24/$CR$18 -> 0.092236402 | DY24: =($CU$12+$CW$12/$CR$18+$CY$12/$CR$18^3+$DA$12/$CR$18^4+$DC$12/$CR$18^5)*DX24 -> -0.032466415 | DZ24: =($DE$12+$DG$12/$CR$18+$CU$13/$CR$18^2)*DX24^2 -> 0.0016881199 | EA24: =$CW$13*($DG$12/$CR$18+$CU$13/$CR$18^2)*DX24^5 -> -2.4608956e-07 | EB24: =$CY$13*(1+$DA$13*DX24^2)*DX24^2/$CR$18^3 -> 0.00087355922 | EC24: =EXP(-$DA$13*DX24^2) -> 0.99388483 | ED24: =1+DY24+DZ24-EA24+EB24*EC24 -> 0.97009017 | EE24: =ED24-DW24 -> -0.0007248127 | EF24: =(EE24-DV24)/(DW24-DN24) -> -0.96824839 | EG24: =DN24-DV24/EF24 -> 0.9700664 | EK24: =K24 -> 402.19642 | EU24: =(EK24*$EO$18)/(DM24*10.73*$EJ$18) -> 1.0691902 | EV24: =EU24/67.0176 -> 0.015953871 | EW24: =EXP($ES$18*EV24^$ET$18) -> 1.0222649 | EX24: =$ER$18*10^-4*EW24 -> 0.014018874 | EZ24: 709.5 | FA24: 4490.8 | FC24: 2141.6 | FD24: 4960.8
C25: =E24 -> 519.20284 | D25: 315.5 | E25: =CK25 -> 549.74265 | F25: =D25-E25 -> -234.24265 | G25: =AVERAGE(C25,D25) -> 417.35142 | I25: =Sheet10!K25 -> 547.44323 | K25: =G25 -> 417.35142 | O25: =(($P$8*K25^1.187)/56.06)*10^(10.393*$N$18) -> 50.375963 | Q25: =1+(4.67*10^-4*O25)+(0.11*10^-4*$P$18)+(0.1337*10^-8*O25*$P$18) -> 1.1033352 | R25: =0.0283*AS25*($M$18)/K25 -> 0.04468078 | S25: =$P$3*($P$4+Q25) -> 5516.6761 | T25: =S25*5.615 -> 30976.136 | U25: =IF($P$5>0,R25*($P$10-O25)*$P$3,0) -> 44596.789 | V25: =$X$14+$Y$13*(O25-$W$14) -> 0.88424275 | W25: =(8830/(131.5+$P$9)) -> 54.006116 | X25: =0.01361*V25*O25 -> 0.60625173 | Y25: =(W25+X25)/Q25 -> 49.49753 | Z25: =($P$4*$T$6)+(Q25*Y25) -> 54.612368 | AA25: =$P$4+Q25 -> 1.1033352 | AB25: =Z25/AA25 -> 49.49753 | AG25: =10.715*(O25+100)^-0.515 -> 0.81048557 | AH25: =5.44*(O25+150)^-0.338 -> 0.90693274 | AI25: =AG25*$AF$18^AH25 -> 1.4300762 | AJ25: =(($P$4*$T$6)/($P$4*$T$6+Q25*Y25))*$T$7 -> 0 | AK25: =((Q25*Y25)/($P$4*$T$6+Q25*Y25))*AI25 -> 1.4300762 | AL25: =AJ25+AK25 -> 1.4300762 | AM25: =(($P$4*$T$6)/($P$4*$T$6+Q25*Y25))*$T$8 -> 0 | AN25: =((Q25*Y25)/($P$4*$T$6+Q25*Y25))*$T$4 -> 30 | AO25: =AM25+AN25 -> 30 | AQ25: =CS25 -> 0.62571427 | AS25: =EG25 -> 0.96900785 | AU25: =(T25)*(1/86400)/$T$10 -> 4.1083281 | AV25: =(U25)*(1/86400)/$T$10 -> 5.914819 | AW25: =AU25+AV25 -> 10.023147 | AX25: =AU25/AW25 -> 0.40988404 | AY25: =1-AX25 -> 0.59011596 | AZ25: =1.071-(0.2218*((AW25^2)/($T$9))) -> -65.777397 | BA25: =IF(AZ25<0.13,0.13,AZ25) -> 0.13 | BB25: =1.938*AU25*(AB25/AO25)^(1/4) -> 9.023696 | BC25: =1.938*AV25*(AB25/AO25)^(1/4) -> 12.991545 | BD25: =120.872*$T$9*SQRT(AB25/AO25) -> 51.753007 | BE25: =0.15726*AL25*(1/(AB25*AO25^3))^(1/4) -> 0.0066144026 | BF25: =0.0019+0.0322*BE25-0.6642*BE25^2+4.9951*BE25^3 -> 0.0020853703 | BG25: =1-10.0147*BE25+33.8696*BE25^2+277.2817*BE25^3 -> 0.93532079 | BH25: =BF25/BG25 -> 0.0022295776 | BI25: =BB25*($K$18^0.1)*BH25 -> 0.035760504 | BJ25: =(BC25^0.575)*(14.7^0.1)*BD25 -> 295.81642 | BK25: =BI25/BJ25 -> 0.00012088748 | BL25: =(0.0047+1123.32*BK25+729489.64*BK25^2) -> 0.15115593 | BM25: =(1+1097.1566*BK25+722153.97*BK25^2) -> 1.1431859 | BN25: =SQRT(BL25/BM25) -> 0.36362536 | BO25: =(BC25*BE25^0.38)/BD25^2.14 -> 0.00041459597 | BP25: =1.0886-69.9473*BO25+2334.3497*BO25^2-12896.683*BO25^3 -> 1.0600005 | BQ25: =1-53.4401*BO25+1517.9369*BO25^2-8419.8115*BO25^3 -> 0.97810427 | BR25: =BP25/BQ25 -> 1.0837295 | BS25: =IF(U25<=0,1,(BN25*BR25)) -> 0.39407154 | BT25: =IF(U25>1,BN25*BR25,1) -> 0.39407154 | BU25: =IF($P$5=0,1,BT25) -> 0.39407154 | BV25: =AB25*AU25 -> 203.35209 | BW25: =EU25*AV25 -> 6.569471 | BX25: =$T$10*(BV25+BW25)*86400 -> 1582775 | BY25: =(AL25^BS25)*EX25^(1-BS25) -> 0.086808235 | BZ25: =2.2*10^-2*BX25/BY25/$T$9 -> 1203378.3 | CA25: =$CB$15/3.7065 -> 0.00016187778 | CB25: =5.0452/BZ25 -> 4.1925302e-06 | CC25: =LOG(($CB$15^1.1098/2.8257)+(7.149/BZ25)^0.8981) -> -3.9420364 | CD25: =-4*LOG(CA25-(CB25*CC25)) -> 14.994373 | CE25: =1/CD25^2 -> 0.0044477808 | CF25: =BS25*AB25+(1-BS25)*EU25 -> 20.17856 | CG25: =CE25*BX25^2/($T$9)^5/CF25 -> 1.341831e+11 | CH25: =(1/144)*(CF25+(CG25/74130000000)) -> 0.15269907 | CI25: =CH25*$CI$14 -> 30.539814 | CJ25: =CJ24+200 -> 1600 | CK25: =C25+CI25 -> 549.74265 | CS25: =K25/$CQ$18 -> 0.62571427 | CT25: 0.8 | CU25: =0.27*CS25/CT25/$CR$18 -> 0.11614821 | CV25: =($CU$12+$CW$12/$CR$18+$CY$12/$CR$18^3+$DA$12/$CR$18^4+$DC$12/$CR$18^5)*CU25 -> -0.040883165 | CW25: =($DE$12+$DG$12/$CR$18+$CU$13/$CR$18^2)*CU25^2 -> 0.0026768475 | CX25: =$CW$13*($DG$12/$CR$18+$CU$13/$CR$18^2)*CU25^5 -> -7.7919124e-07 | CY25: =$CY$13*(1+$DA$13*CU25^2)*(CU25^2/$CR$18^3) -> 0.0013901469 | CZ25: =EXP(-$DA$13*CU25^2) -> 0.99032057 | DA25: =1+CV25+CW25-CX25+CY25*CZ25 -> 0.96317115 | DB25: =DA25-CT25 -> 0.16317115 | DC25: 0.85 | DD25: =0.27*CS25/DC25/$CR$18 -> 0.10931596 | DE25: =($CU$12+$CW$12/$CR$18+$CY$12/$CR$18^3+$DA$12/$CR$18^4+$DC$12/$CR$18^5)*DD25 -> -0.038478273 | DF25: =($DE$12+$DG$12/$CR$18+$CU$13/$CR$18^2)*DD25^2 -> 0.0023711867 | DG25: =$CW$13*($DG$12/$CR$18+$CU$13/$CR$18^2)*DD25^5 -> -5.754391e-07 | DH25: =$CY$13*(1+$DA$13*DD25^2)*DD25^2/$CR$18^3 -> 0.0012300559 | DI25: =EXP(-$DA$13*DD25^2) -> 0.99142108 | DJ25: =1+DE25+DF25-DG25+DH25*DI25 -> 0.96511299 | DK25: =DJ25-DC25 -> 0.11511299 | DL25: =(DK25-DB25)/(DC25-CT25) -> -0.9611632 | DM25: =CT25-DB25/DL25 -> 0.96976425 | DN25: =DC25 -> 0.85 | DO25: =0.27*CS25/DN25/$CR$18 -> 0.10931596 | DP25: =($CU$12+$CW$12/$CR$18+$CY$12/$CR$18^3+$DA$12/$CR$18^4+$DC$12/$CR$18^5)*DO25 -> -0.038478273 | DQ25: =($DE$12+$DG$12/$CR$18+$CU$13/$CR$18^2)*DO25^2 -> 0.0023711867 | DR25: =$CW$13*($DG$12/$CR$18+$CU$13/$CR$18^2)*DO25^5 -> -5.754391e-07 | DS25: =$CY$13*(1+$DA$13*DO25^2)*(DO25^2/$CR$18^3) -> 0.0012300559 | DT25: =EXP(-$DA$13*DO25^2) -> 0.99142108 | DU25: =1+DP25+DQ25-DR25+DS25*DT25 -> 0.96511299 | DV25: =DU25-DN25 -> 0.11511299 | DW25: =DM25 -> 0.96976425 | DX25: =0.27*CS25/DW25/$CR$18 -> 0.095815626 | DY25: =($CU$12+$CW$12/$CR$18+$CY$12/$CR$18^3+$DA$12/$CR$18^4+$DC$12/$CR$18^5)*DX25 -> -0.033726271 | DZ25: =($DE$12+$DG$12/$CR$18+$CU$13/$CR$18^2)*DX25^2 -> 0.0018216765 | EA25: =$CW$13*($DG$12/$CR$18+$CU$13/$CR$18^2)*DX25^5 -> -2.9768924e-07 | EB25: =$CY$13*(1+$DA$13*DX25^2)*DX25^2/$CR$18^3 -> 0.00094312608 | EC25: =EXP(-$DA$13*DX25^2) -> 0.99340262 | ED25: =1+DY25+DZ25-EA25+EB25*EC25 -> 0.96903261 | EE25: =ED25-DW25 -> -0.0007316453 | EF25: =(EE25-DV25)/(DW25-DN25) -> -0.96727225 | EG25: =DN25-DV25/EF25 -> 0.96900785 | EK25: =K25 -> 417.35142 | EU25: =(EK25*$EO$18)/(DM25*10.73*$EJ$18) -> 1.11068 | EV25: =EU25/67.0176 -> 0.01657296 | EW25: =EXP($ES$18*EV25^$ET$18) -> 1.0234215 | EX25: =$ER$18*10^-4*EW25 -> 0.014034734 | EZ25: 852.3 | FA25: 5140.8 | FC25: 2584.2 | FD25: 5999
C26: =E25 -> 549.74265 | D26: 315.6 | E26: =CK26 -> 580.61214 | F26: =D26-E26 -> -265.01214 | G26: =AVERAGE(C26,D26) -> 432.67133 | I26: =Sheet10!K26 -> 581.39009 | K26: =G26 -> 432.67133 | O26: =(($P$8*K26^1.187)/56.06)*10^(10.393*$N$18) -> 52.578391 | Q26: =1+(4.67*10^-4*O26)+(0.11*10^-4*$P$18)+(0.1337*10^-8*O26*$P$18) -> 1.104385 | R26: =0.0283*AS26*($M$18)/K26 -> 0.043051396 | S26: =$P$3*($P$4+Q26) -> 5521.9249 | T26: =S26*5.615 -> 31005.608 | U26: =IF($P$5>0,R26*($P$10-O26)*$P$3,0) -> 42496.379 | V26: =$X$14+$Y$13*(O26-$W$14) -> 0.88399104 | W26: =(8830/(131.5+$P$9)) -> 54.006116 | X26: =0.01361*V26*O26 -> 0.63257683 | Y26: =(W26+X26)/Q26 -> 49.474317 | Z26: =($P$4*$T$6)+(Q26*Y26) -> 54.638693 | AA26: =$P$4+Q26 -> 1.104385 | AB26: =Z26/AA26 -> 49.474317 | AG26: =10.715*(O26+100)^-0.515 -> 0.80443927 | AH26: =5.44*(O26+150)^-0.338 -> 0.90358794 | AI26: =AG26*$AF$18^AH26 -> 1.4164382 | AJ26: =(($P$4*$T$6)/($P$4*$T$6+Q26*Y26))*$T$7 -> 0 | AK26: =((Q26*Y26)/($P$4*$T$6+Q26*Y26))*AI26 -> 1.4164382 | AL26: =AJ26+AK26 -> 1.4164382 | AM26: =(($P$4*$T$6)/($P$4*$T$6+Q26*Y26))*$T$8 -> 0 | AN26: =((Q26*Y26)/($P$4*$T$6+Q26*Y26))*$T$4 -> 30 | AO26: =AM26+AN26 -> 30 | AQ26: =CS26 -> 0.64868265 | AS26: =EG26 -> 0.96794348 | AU26: =(T26)*(1/86400)/$T$10 -> 4.1122369 | AV26: =(U26)*(1/86400)/$T$10 -> 5.6362441 | AW26: =AU26+AV26 -> 9.7484811 | AX26: =AU26/AW26 -> 0.42183361 | AY26: =1-AX26 -> 0.57816639 | AZ26: =1.071-(0.2218*((AW26^2)/($T$9))) -> -62.16388 | BA26: =IF(AZ26<0.13,0.13,AZ26) -> 0.13 | BB26: =1.938*AU26*(AB26/AO26)^(1/4) -> 9.0312225 | BC26: =1.938*AV26*(AB26/AO26)^(1/4) -> 12.37822 | BD26: =120.872*$T$9*SQRT(AB26/AO26) -> 51.74087 | BE26: =0.15726*AL26*(1/(AB26*AO26^3))^(1/4) -> 0.0065520924 | BF26: =0.0019+0.0322*BE26-0.6642*BE26^2+4.9951*BE26^3 -> 0.0020838684 | BG26: =1-10.0147*BE26+33.8696*BE26^2+277.2817*BE26^3 -> 0.93591477 | BH26: =BF26/BG26 -> 0.0022265578 | BI26: =BB26*($K$18^0.1)*BH26 -> 0.035741855 | BJ26: =(BC26^0.575)*(14.7^0.1)*BD26 -> 287.63646 | BK26: =BI26/BJ26 -> 0.00012426052 | BL26: =(0.0047+1123.32*BK26+729489.64*BK26^2) -> 0.15554814 | BM26: =(1+1097.1566*BK26+722153.97*BK26^2) -> 1.1474838 | BN26: =SQRT(BL26/BM26) -> 0.3681791 | BO26: =(BC26*BE26^0.38)/BD26^2.14 -> 0.00039380246 | BP26: =1.0886-69.9473*BO26+2334.3497*BO26^2-12896.683*BO26^3 -> 1.0614158 | BQ26: =1-53.4401*BO26+1517.9369*BO26^2-8419.8115*BO26^3 -> 0.97919005 | BR26: =BP26/BQ26 -> 1.0839732 | BS26: =IF(U26<=0,1,(BN26*BR26)) -> 0.39909629 | BT26: =IF(U26>1,BN26*BR26,1) -> 0.39909629 | BU26: =IF($P$5=0,1,BT26) -> 0.39909629 | BV26: =AB26*AU26 -> 203.45011 | BW26: =EU26*AV26 -> 6.49694 | BX26: =$T$10*(BV26+BW26)*86400 -> 1582967.2 | BY26: =(AL26^BS26)*EX26^(1-BS26) -> 0.0885713 | BZ26: =2.2*10^-2*BX26/BY26/$T$9 -> 1179567.6 | CA26: =$CB$15/3.7065 -> 0.00016187778 | CB26: =5.0452/BZ26 -> 4.2771606e-06 | CC26: =LOG(($CB$15^1.1098/2.8257)+(7.149/BZ26)^0.8981) -> -3.9406451 | CD26: =-4*LOG(CA26-(CB26*CC26)) -> 14.991185 | CE26: =1/CD26^2 -> 0.0044496725 | CF26: =BS26*AB26+(1-BS26)*EU26 -> 20.437682 | CG26: =CE26*BX26^2/($T$9)^5/CF26 -> 1.3257038e+11 | CH26: =(1/144)*(CF26+(CG26/74130000000)) -> 0.15434745 | CI26: =CH26*$CI$14 -> 30.869489 | CJ26: =CJ25+200 -> 1800 | CK26: =C26+CI26 -> 580.61214 | CS26: =K26/$CQ$18 -> 0.64868265 | CT26: 0.8 | CU26: =0.27*CS26/CT26/$CR$18 -> 0.12041172 | CV26: =($CU$12+$CW$12/$CR$18+$CY$12/$CR$18^3+$DA$12/$CR$18^4+$DC$12/$CR$18^5)*CU26 -> -0.042383882 | CW26: =($DE$12+$DG$12/$CR$18+$CU$13/$CR$18^2)*CU26^2 -> 0.0028769749 | CX26: =$CW$13*($DG$12/$CR$18+$CU$13/$CR$18^2)*CU26^5 -> -9.3309349e-07 | CY26: =$CY$13*(1+$DA$13*CU26^2)*(CU26^2/$CR$18^3) -> 0.0014951535 | CZ26: =EXP(-$DA$13*CU26^2) -> 0.98960069 | DA26: =1+CV26+CW26-CX26+CY26*CZ26 -> 0.96197363 | DB26: =DA26-CT26 -> 0.16197363 | DC26: 0.85 | DD26: =0.27*CS26/DC26/$CR$18 -> 0.11332867 | DE26: =($CU$12+$CW$12/$CR$18+$CY$12/$CR$18^3+$DA$12/$CR$18^4+$DC$12/$CR$18^5)*DD26 -> -0.039890712 | DF26: =($DE$12+$DG$12/$CR$18+$CU$13/$CR$18^2)*DD26^2 -> 0.0025484622 | DG26: =$CW$13*($DG$12/$CR$18+$CU$13/$CR$18^2)*DD26^5 -> -6.8909717e-07 | DH26: =$CY$13*(1+$DA$13*DD26^2)*DD26^2/$CR$18^3 -> 0.001322862 | DI26: =EXP(-$DA$13*DD26^2) -> 0.99078266 | DJ26: =1+DE26+DF26-DG26+DH26*DI26 -> 0.96396911 | DK26: =DJ26-DC26 -> 0.11396911 | DL26: =(DK26-DB26)/(DC26-CT26) -> -0.96009047 | DM26: =CT26-DB26/DL26 -> 0.96870663 | DN26: =DC26 -> 0.85 | DO26: =0.27*CS26/DN26/$CR$18 -> 0.11332867 | DP26: =($CU$12+$CW$12/$CR$18+$CY$12/$CR$18^3+$DA$12/$CR$18^4+$DC$12/$CR$18^5)*DO26 -> -0.039890712 | DQ26: =($DE$12+$DG$12/$CR$18+$CU$13/$CR$18^2)*DO26^2 -> 0.0025484622 | DR26: =$CW$13*($DG$12/$CR$18+$CU$13/$CR$18^2)*DO26^5 -> -6.8909717e-07 | DS26: =$CY$13*(1+$DA$13*DO26^2)*(DO26^2/$CR$18^3) -> 0.001322862 | DT26: =EXP(-$DA$13*DO26^2) -> 0.99078266 | DU26: =1+DP26+DQ26-DR26+DS26*DT26 -> 0.96396911 | DV26: =DU26-DN26 -> 0.11396911 | DW26: =DM26 -> 0.96870663 | DX26: =0.27*CS26/DW26/$CR$18 -> 0.099441224 | DY26: =($CU$12+$CW$12/$CR$18+$CY$12/$CR$18^3+$DA$12/$CR$18^4+$DC$12/$CR$18^5)*DX26 -> -0.03500245 | DZ26: =($DE$12+$DG$12/$CR$18+$CU$13/$CR$18^2)*DX26^2 -> 0.0019621468 | EA26: =$CW$13*($DG$12/$CR$18+$CU$13/$CR$18^2)*DX26^5 -> -3.5843773e-07 | EB26: =$CY$13*(1+$DA$13*DX26^2)*DX26^2/$CR$18^3 -> 0.001016366 | EC26: =EXP(-$DA$13*DX26^2) -> 0.99289571 | ED26: =1+DY26+DZ26-EA26+EB26*EC26 -> 0.9679692 | EE26: =ED26-DW26 -> -0.00073743333 | EF26: =(EE26-DV26)/(DW26-DN26) -> -0.9663027 | EG26: =DN26-DV26/EF26 -> 0.96794348 | EK26: =K26 -> 432.67133 | EU26: =(EK26*$EO$18)/(DM26*10.73*$EJ$18) -> 1.1527073 | EV26: =EU26/67.0176 -> 0.017200069 | EW26: =EXP($ES$18*EV26^$ET$18) -> 1.0246084 | EX26: =$ER$18*10^-4*EW26 -> 0.014051011 | EZ26: 982.9 | FA26: 5809.9 | FC26: 2966.7 | FD26: 6979.3
