Workbook

Sheet Sheet1
N3: q0 | O3: 100 | P3: STB/d | R3: qw | S3: =O3*O4 -> 0 | T3: STB water/STB | V3: At Bubble Point
N4: WOR | O4: 0 | P4: STB Water/STB | R4: s oil | S4: 30 | T4: dyne/cm | V4: Rs | W4: 250 | X4: scf/STB
N5: GLR | O5: 250 | P5: scf/STB | R5: g w | S5: 1.074 | V5: Pb | W5: 1697 | X5: Psi
N6: g g | O6: 0.65 | R6: r w | S6: =S5*62.4 -> 67.0176 | T6: lbm/ft3 | V6: Bob | W6: 1.2 | X6: res bbl/STB
N7: Psep | O7: 100 | P7: psig | R7: m w | S7: 1 | T7: cp | V7: rob | W7: 48.33 | X7: lbm/ft3
N8: g sep | O8: 0.71 | R8: sw | S8: 72 | T8: dyne/cm
N9: g l | O9: 28 | P9: 0API | R9: D | S9: =2/12 -> 0.16666667 | T9: ft | V9: C0 | W9: =(-1.433+5*$W$4+17.2*$M$19-1.18*$O$8+12.61*$O$9)/($S$11*10^5) -> 2.1703786e-05
N10: GOR | O10: =O12/O3 -> 250 | P10: scf/STB | R10: Area | S10: =(3.1416/4)*(S9)^2 -> 0.021816667 | T10: ft2
N11: ql | O11: =O3+S3 -> 100 | P11: STB/d | R11: P | S11: 5651 | T11: Psi
N12: qg | O12: =O5*O11 -> 25000 | P12: scf/d
X13: Rs | Y13: g gd | Z13: slope | CU13: A1 | CV13: 0.3265 | CW13: A2 | CX13: -1.07 | CY13: A3 | CZ13: =-0.5339 -> -0.5339 | DA13: A4 | DB13: =0.01569 -> 0.01569 | DC13: A5 | DD13: =-0.05165 -> -0.05165 | DE13: A6 | DF13: 0.5475 | DG13: A7 | DH13: -0.7361
X14: 1400 | Y14: 0.67 | Z14: =SLOPE(Y14:Y15,X14:X15) -> -0.0001 | CU14: A8 | CV14: =0.1844 -> 0.1844 | CW14: A9 | CX14: =0.1056 -> 0.1056 | CY14: A10 | CZ14: =0.6134 -> 0.6134 | DA14: A11 | DB14: 0.721
X15: 0 | Y15: 0.81 | AR15: From DAK | CI15: DL | CJ15: 200 | CK15: ft | CO15: DAK Correlation | EJ15: LGE Correlation
CB16: e | CC16: 0.0006 | CD16: (assumed)
N17: Const. T | P17: Const. T | W17: from fig:3.4 | BT17: For qg=0 or <1 | BU17: For yl >1 | BV17: For GLR=0
C18: P (psia) | D18: P (assumed) | E18: P (output) | F18: Err | G18: p(avg) | I18: P (OUTPUT) | K18: P (avg) | L18: T0F (const.) | M18: T0 R (const.) | N18: A | O18: Rs (scf/STB) | P18: F | R18: B0 (res bbl/STB) | S18: Bg (res ft3/SCF) | T18: ql (res bbl/d) | U18: ql (res ft3/d) | V18: qg (res ft3/d) | W18: γgd | X18: ρ0 (part1) | Y18: ρ0 (part 2) | Z18: ρ0 (lb / ft3) | AA18: ρl (part 1) | AB18: ρl (part 2) | AC18: ρl (lbm/ft3) | AD18: C | AE18: B | AF18: A | AG18: m od | AH18: a | AI18: b | AJ18: m o (cp) | AK18: Weight 1 | AL18: Weight 2 | AM18: ml (cp) | AN18: weight 1 | AO18: weight 2 | AP18: s l (dyne/cm) | AR18: Ppr | AS18: Tpr | AT18: Z | AV18: usl (ft/s) | AW18: usg (ft/s) | AX18: um (ft/s) | AY18: l l | AZ18: l g | BA18: LB | BB18: LB(final) | BC18: Nvl | BD18: Nvg | BE18: ND | BF18: NL | BG18: CNL(1) | BH18: CNL(2) | BI18: CNL | BJ18: H(1) | BK18: H(2) | BL18: H | BM18: y1/(1) | BN18: y1/(2) | BO18: y1/ | BP18: B | BQ18: (1) | BR18: (2) | BS18:  | BT18: yl | BU18: yl | BV18: yl | BW18: m(1) | BX18: m(2) | BY18: m (lbm/d) | BZ18: m m | CA18: Nre | CB18: f(1) | CC18: f(2) | CD18: f(3) | CE18: 1/sqrt(f) | CF18: f | CG18: r(avg) | CH18: fm2/D5rho | CI18: dp/dl | CJ18: DP | CK18: L | CL18: P (psi) | CO18: T (0F) | CP18: T (0R) | CQ18: Tc (0R) | CR18: Pc | CS18: Tpr | CT18: Ppr | CU18: Z | CV18: ρpr | CW18: Part 1 | CX18: Part 2 | CY18: Part 3 | CZ18: Part 4 | DA18: Part 5 | DB18: Z(1) | DC18: Err(1) | DD18: Z | DE18: ρpr | DF18: Part 1 | DG18: Part 2 | DH18: Part 3 | DI18: Part 4 | DJ18: Part 5 | DK18: Z(2) | DL18: Err(2) | DM18: Slope | DN18: Z | DO18: Z | DP18: ρpr | DQ18: Part 1 | DR18: Part 2 | DS18: Part 3 | DT18: Part 4 | DU18: Part 5 | DV18: Z(1) | DW18: Err(1) | DX18: Z | DY18: ρpr | DZ18: Part 1 | EA18: Part 2 | EB18: Part 3 | EC18: Part 4 | ED18: Part 5 | EE18: Z(2) | EF18: Err(2) | EG18: Slope | EH18: Z | EJ18: T (0F) | EK18: T (0R) | EL18: P (psi) | EM18: Tc (0R) | EN18: Pc (psi) | EO18: γg | EP18: MW | EQ18: A1 | ER18: A2 | ES18: A | ET18: B | EU18: C | EV18: ρg (lbm/ft3) | EW18: ρg (g/cm3) | EX18: EXP(Bρgc) | EY18: µg (cp)
C19: 514.7 | D19: 514.8 | E19: =CL19 -> 545.76602 | F19: =D19-E19 -> -30.966015 | G19: =AVERAGE(C19,D19) -> 514.75 | I19: =Sheet10!K18 -> 531.43535 | K19: =G19 -> 514.75 | L19: 160 | M19: =460+L19 -> 620 | N19: =$O$9/($L$19+460) -> 0.04516129 | O19: =(($O$8*K19^1.0937)/27.64)*10^(11.172*$N$19) -> 75.846436 | P19: =($L$19-60)*($O$9/$O$8) -> 3943.662 | R19: =$W$6*EXP($W$9*(1697-G19)) -> 1.2311896 | S19: =0.0283*AT19*($M$19)/K19 -> 0.032287515 | T19: =$O$3*($O$4+R19) -> 123.11896 | U19: =T19*5.615 -> 691.31296 | V19: =IF($O$5>0,S19*($O$10-O19)*$O$3,0) -> 562.29859 | W19: =$Y$15+$Z$14*(O19-$X$15) -> 0.80241536 | X19: =$W$7 -> 48.33 | Y19: =R19/$W$6 -> 1.0259913 | Z19: =X19*Y19 -> 49.586161 | AA19: =($S$6*$O$4)+(R19*Z19) -> 61.049966 | AB19: =$O$4+R19 -> 1.2311896 | AC19: =AA19/AB19 -> 49.586161 | AD19: =3.0324-0.02023*$O$9 -> 2.46596 | AE19: =10^$AD$19 -> 292.38831 | AF19: =$AE$19*$L$19^-1.163 -> 0.79903989 | AG19: =10^$AF$19-1 -> 5.29564 | AH19: =10.715*(O19+100)^-0.515 -> 0.74773617 | AI19: =5.44*(O19+150)^-0.338 -> 0.87098369 | AJ19: =AH19*$AG$19^AI19 -> 3.1935194 | AK19: =(($O$4*$S$6)/($O$4*$S$6+R19*Z19))*$S$7 -> 0 | AL19: =((R19*Z19)/($O$4*$S$6+R19*Z19))*AJ19 -> 3.1935194 | AM19: =AK19+AL19 -> 3.1935194 | AN19: =(($O$4*$S$6)/($O$4*$S$6+R19*Z19))*$S$8 -> 0 | AO19: =((R19*Z19)/($O$4*$S$6+R19*Z19))*$S$4 -> 30 | AP19: =AN19+AO19 -> 30 | AR19: =CT19 -> 0.77173913 | AS19: =CS19 -> 1.657754 | AT19: =EH19 -> 0.94722436 | AV19: =(U19)*(1/86400)/$S$10 -> 0.36675206 | AW19: =(V19)*(1/86400)/$S$10 -> 0.29830797 | AX19: =AV19+AW19 -> 0.66506003 | AY19: =AV19/AX19 -> 0.55145708 | AZ19: =1-AY19 -> 0.44854292 | BA19: =1.071-(0.2218*((AX19^2)/($S$9))) -> 0.48238072 | BB19: =IF(BA19<0.13,0.13,BA19) -> 0.48238072 | BC19: =1.938*AV19*(AC19/AP19)^(1/4) -> 0.80590925 | BD19: =1.938*AW19*(AC19/AP19)^(1/4) -> 0.65550866 | BE19: =120.872*$S$9*SQRT(AC19/AP19) -> 25.899661 | BF19: =0.15726*AM19*(1/(AC19*AP19^3))^(1/4) -> 0.014764093 | BG19: =0.0019+0.0322*BF19-0.6642*BF19^2+4.9951*BF19^3 -> 0.002246698 | BH19: =1-10.0147*BF19+33.8696*BF19^2+277.2817*BF19^3 -> 0.86041725 | BI19: =BG19/BH19 -> 0.0026111727 | BJ19: =BC19*($K$19^0.1)*BI19 -> 0.0039289941 | BK19: =(BD19^0.575)*(14.7^0.1)*BE19 -> 26.58021 | BL19: =BJ19/BK19 -> 0.00014781652 | BM19: =(0.0047+1123.32*BL19+729489.64*BL19^2) -> 0.1866844 | BN19: =(1+1097.1566*BL19+722153.97*BL19^2) -> 1.1779567 | BO19: =SQRT(BM19/BN19) -> 0.3980974 | BP19: =(BD19*BF19^0.38)/BE19^2.14 -> 0.00012486125 | BQ19: =1.0886-69.9473*BP19+2334.3497*BP19^2-12896.683*BP19^3 -> 1.0799027 | BR19: =1-53.4401*BP19+1517.9369*BP19^2-8419.8115*BP19^3 -> 0.99335105 | BS19: =BQ19/BR19 -> 1.0871309 | BT19: =IF(V19<=0,1,(BO19*BS19)) -> 0.432784 | BU19: =IF(V19>1,BO19*BS19,1) -> 0.432784 | BV19: =IF($O$5=0,1,BU19) -> 0.432784 | BW19: =AC19*AV19 -> 18.185827 | BX19: =EV19*AW19 -> 0.45841666 | BY19: =$S$10*(BW19+BX19)*86400 -> 35143.653 | BZ19: =(AM19^BT19)*EY19^(1-BT19) -> 0.14114761 | CA19: =2.2*10^-2*BY19/BZ19/$S$9 -> 32866.033 | CB19: =$CC$16/3.7065 -> 0.00016187778 | CC19: =5.0452/CA19 -> 0.00015350803 | CD19: =LOG(($CC$16^1.1098/2.8257)+(7.149/CA19)^0.8981) -> -3.2162916 | CE19: =-4*LOG(CB19-(CC19*CD19)) -> 12.733433 | CF19: =1/CE19^2 -> 0.0061674979 | CG19: =BT19*AC19+(1-BT19)*EV19 -> 22.331751 | CH19: =CF19*BY19^2/($S$9)^5/CG19 -> 2.6523833e+09 | CI19: =(1/144)*(CG19+(CH19/74130000000)) -> 0.15533008 | CJ19: =CI19*$CJ$15 -> 31.066015 | CK19: 200 | CL19: =C19+CJ19 -> 545.76602 | CO19: =L19 -> 160 | CP19: =CO19+460 -> 620 | CQ19: 374 | CR19: 667 | CS19: =CP19/CQ19 -> 1.657754 | CT19: =K19/$CR$19 -> 0.77173913 | CU19: 0.8 | CV19: =0.27*CT19/CU19/$CS$19 -> 0.15711737 | CW19: =($CV$13+$CX$13/$CS$19+$CZ$13/$CS$19^3+$DB$13/$CS$19^4+$DD$13/$CS$19^5)*CV19 -> -0.068847576 | CX19: =($DF$13+$DH$13/$CS$19+$CV$14/$CS$19^2)*CV19^2 -> 0.0042105504 | CY19: =$CX$14*($DH$13/$CS$19+$CV$14/$CS$19^2)*CV19^5 -> -3.8111075e-06 | CZ19: =$CZ$14*(1+$DB$14*CV19^2)*(CV19^2/$CS$19^3) -> 0.0033829357 | DA19: =EXP(-$DB$14*CV19^2) -> 0.98235895 | DB19: =1+CW19+CX19-CY19+CZ19*DA19 -> 0.93869004 | DC19: =DB19-CU19 -> 0.13869004 | DD19: 0.85 | DE19: =0.27*CT19/DD19/$CS$19 -> 0.14787518 | DF19: =($CV$13+$CX$13/$CS$19+$CZ$13/$CS$19^3+$DB$13/$CS$19^4+$DD$13/$CS$19^5)*DE19 -> -0.064797719 | DG19: =($DF$13+$DH$13/$CS$19+$CV$14/$CS$19^2)*DE19^2 -> 0.0037297609 | DH19: =$CX$14*($DH$13/$CS$19+$CV$14/$CS$19^2)*DE19^5 -> -2.814534e-06 | DI19: =$CZ$14*(1+$DB$14*DE19^2)*DE19^2/$CS$19^3 -> 0.0029906652 | DJ19: =EXP(-$DB$14*DE19^2) -> 0.98435748 | DK19: =1+DF19+DG19-DH19+DI19*DJ19 -> 0.94187874 | DL19: =DK19-DD19 -> 0.09187874 | DM19: =(DL19-DC19)/(DD19-CU19) -> -0.93622604 | DN19: =CU19-DC19/DM19 -> 0.94813735 | DO19: =DD19 -> 0.85 | DP19: =0.27*CT19/DO19/$CS$19 -> 0.14787518 | DQ19: =($CV$13+$CX$13/$CS$19+$CZ$13/$CS$19^3+$DB$13/$CS$19^4+$DD$13/$CS$19^5)*DP19 -> -0.064797719 | DR19: =($DF$13+$DH$13/$CS$19+$CV$14/$CS$19^2)*DP19^2 -> 0.0037297609 | DS19: =$CX$14*($DH$13/$CS$19+$CV$14/$CS$19^2)*DP19^5 -> -2.814534e-06 | DT19: =$CZ$14*(1+$DB$14*DP19^2)*(DP19^2/$CS$19^3) -> 0.0029906652 | DU19: =EXP(-$DB$14*DP19^2) -> 0.98435748 | DV19: =1+DQ19+DR19-DS19+DT19*DU19 -> 0.94187874 | DW19: =DV19-DO19 -> 0.09187874 | DX19: =DN19 -> 0.94813735 | DY19: =0.27*CT19/DX19/$CS$19 -> 0.13256929 | DZ19: =($CV$13+$CX$13/$CS$19+$CZ$13/$CS$19^3+$DB$13/$CS$19^4+$DD$13/$CS$19^5)*DY19 -> -0.058090804 | EA19: =($DF$13+$DH$13/$CS$19+$CV$14/$CS$19^2)*DY19^2 -> 0.0029976184 | EB19: =$CX$14*($DH$13/$CS$19+$CV$14/$CS$19^2)*DY19^5 -> -1.6298396e-06 | EC19: =$CZ$14*(1+$DB$14*DY19^2)*DY19^2/$CS$19^3 -> 0.0023962819 | ED19: =EXP(-$DB$14*DY19^2) -> 0.98740864 | EE19: =1+DZ19+EA19-EB19+EC19*ED19 -> 0.94727455 | EF19: =EE19-DX19 -> -0.0008627938 | EG19: =(EF19-DW19)/(DX19-DO19) -> -0.94501774 | EH19: =DO19-DW19/EG19 -> 0.94722436 | EJ19: =L19 -> 160 | EK19: =460+EJ19 -> 620 | EL19: =K19 -> 514.75 | EM19: =CQ19 -> 374 | EN19: =CR19 -> 667 | EO19: 0.65 | EP19: =28.97*$EO$19 -> 18.8305 | EQ19: =((9.379+0.01607*$EP$19)*$EK$19^1.5) -> 149463.43 | ER19: =209.2+19.26*EP19+EK19 -> 1191.8754 | ES19: =EQ19/ER19 -> 125.40189 | ET19: =3.448+(986.4/EK19)+0.01009*EP19 -> 5.2289675 | EU19: =2.447-0.2224*ET19 -> 1.2840776 | EV19: =(EL19*$EP$19)/(DN19*10.73*$EK$19) -> 1.5367228 | EW19: =EV19/67.0176 -> 0.022930138 | EX19: =EXP($ET$19*EW19^$EU$19) -> 1.0418784 | EY19: =$ES$19*10^-4*EX19 -> 0.013065352
C20: =E19 -> 545.76602 | D20: 514.9 | E20: =CL20 -> 577.16051 | F20: =D20-E20 -> -62.260514 | G20: =AVERAGE(C20,D20) -> 530.33301 | I20: =Sheet10!K19 -> 563.53515 | K20: =G20 -> 530.33301 | O20: =(($O$8*K20^1.0937)/27.64)*10^(11.172*$N$19) -> 78.361206 | R20: =$W$6*EXP($W$9*(1697-G20)) -> 1.2307733 | S20: =0.0283*AT20*($M$19)/K20 -> 0.031288939 | T20: =$O$3*($O$4+R20) -> 123.07733 | U20: =T20*5.615 -> 691.07919 | V20: =IF($O$5>0,S20*($O$10-O20)*$O$3,0) -> 537.03957 | W20: =$Y$15+$Z$14*(O20-$X$15) -> 0.80216388 | X20: =$W$7 -> 48.33 | Y20: =R20/$W$6 -> 1.0256444 | Z20: =X20*Y20 -> 49.569393 | AA20: =($O$4*$S$6)+(R20*Z20) -> 61.008685 | AB20: =$O$4+R20 -> 1.2307733 | AC20: =AA20/AB20 -> 49.569393 | AH20: =10.715*(O20+100)^-0.515 -> 0.74228805 | AI20: =5.44*(O20+150)^-0.338 -> 0.86772988 | AJ20: =AH20*$AG$19^AI20 -> 3.1531029 | AK20: =(($O$4*$S$6)/($O$4*$S$6+R20*Z20))*$S$7 -> 0 | AL20: =((R20*Z20)/($O$4*$S$6+R20*Z20))*AJ20 -> 3.1531029 | AM20: =AK20+AL20 -> 3.1531029 | AN20: =(($O$4*$S$6)/($O$4*$S$6+R20*Z20))*$S$8 -> 0 | AO20: =((R20*Z20)/($O$4*$S$6+R20*Z20))*$S$4 -> 30 | AP20: =AN20+AO20 -> 30 | AR20: =CT20 -> 0.79510196 | AT20: =EH20 -> 0.94571738 | AV20: =(U20)*(1/86400)/$S$10 -> 0.36662804 | AW20: =(V20)*(1/86400)/$S$10 -> 0.28490768 | AX20: =AV20+AW20 -> 0.65153572 | AY20: =AV20/AX20 -> 0.56271365 | AZ20: =1-AY20 -> 0.43728635 | BA20: =1.071-(0.2218*((AX20^2)/($S$9))) -> 0.50607701 | BB20: =IF(BA20<0.13,0.13,BA20) -> 0.50607701 | BC20: =1.938*AV20*(AC20/AP20)^(1/4) -> 0.80556862 | BD20: =1.938*AW20*(AC20/AP20)^(1/4) -> 0.62600963 | BE20: =120.872*$S$9*SQRT(AC20/AP20) -> 25.895281 | BF20: =0.15726*AM20*(1/(AC20*AP20^3))^(1/4) -> 0.014578474 | BG20: =0.0019+0.0322*BF20-0.6642*BF20^2+4.9951*BF20^3 -> 0.0022437399 | BH20: =1-10.0147*BF20+33.8696*BF20^2+277.2817*BF20^3 -> 0.86205845 | BI20: =BG20/BH20 -> 0.0026027701 | BJ20: =BC20*($K$19^0.1)*BI20 -> 0.0039146954 | BK20: =(BD20^0.575)*(14.7^0.1)*BE20 -> 25.881322 | BL20: =BJ20/BK20 -> 0.00015125562 | BM20: =(0.0047+1123.32*BL20+729489.64*BL20^2) -> 0.19129792 | BN20: =(1+1097.1566*BL20+722153.97*BL20^2) -> 1.1824727 | BO20: =SQRT(BM20/BN20) -> 0.4022162 | BP20: =(BD20*BF20^0.38)/BE20^2.14 -> 0.00011871332 | BQ20: =1.0886-69.9473*BP20+2334.3497*BP20^2-12896.683*BP20^3 -> 1.0803292 | BR20: =1-53.4401*BP20+1517.9369*BP20^2-8419.8115*BP20^3 -> 0.99367733 | BS20: =BQ20/BR20 -> 1.0872032 | BT20: =IF(V20<=0,1,(BO20*BS20)) -> 0.43729075 | BU20: =IF(V20>1,BO20*BS20,1) -> 0.43729075 | BV20: =IF($O$5=0,1,BU20) -> 0.43729075 | BW20: =AC20*AV20 -> 18.17353 | BX20: =EV20*AW20 -> 0.45179935 | BY20: =$S$10*(BW20+BX20)*86400 -> 35108 | BZ20: =(AM20^BT20)*EY20^(1-BT20) -> 0.14402248 | CA20: =2.2*10^-2*BY20/BZ20/$S$9 -> 32177.31 | CB20: =$CC$16/3.7065 -> 0.00016187778 | CC20: =5.0452/CA20 -> 0.00015679372 | CD20: =LOG(($CC$16^1.1098/2.8257)+(7.149/CA20)^0.8981) -> -3.2092991 | CE20: =-4*LOG(CB20-(CC20*CD20)) -> 12.708516 | CF20: =1/CE20^2 -> 0.0061917062 | CG20: =BT20*AC20+(1-BT20)*EV20 -> 22.568567 | CH20: =CF20*BY20^2/($S$9)^5/CG20 -> 2.6295097e+09 | CI20: =(1/144)*(CG20+(CH20/74130000000)) -> 0.15697249 | CJ20: =CI20*$CJ$15 -> 31.394499 | CK20: =CK19+200 -> 400 | CL20: =C20+CJ20 -> 577.16051 | CT20: =K20/$CR$19 -> 0.79510196 | CU20: 0.8 | CV20: =0.27*CT20/CU20/$CS$19 -> 0.16187378 | CW20: =($CV$13+$CX$13/$CS$19+$CZ$13/$CS$19^3+$DB$13/$CS$19^4+$DD$13/$CS$19^5)*CV20 -> -0.070931796 | CX20: =($DF$13+$DH$13/$CS$19+$CV$14/$CS$19^2)*CV20^2 -> 0.0044693409 | CY20: =$CX$14*($DH$13/$CS$19+$CV$14/$CS$19^2)*CV20^5 -> -4.4239755e-06 | CZ20: =$CZ$14*(1+$DB$14*CV20^2)*(CV20^2/$CS$19^3) -> 0.0035947185 | DA20: =EXP(-$DB$14*CV20^2) -> 0.98128489 | DB20: =1+CW20+CX20-CY20+CZ20*DA20 -> 0.93706941 | DC20: =DB20-CU20 -> 0.13706941 | DD20: 0.85 | DE20: =0.27*CT20/DD20/$CS$19 -> 0.1523518 | DF20: =($CV$13+$CX$13/$CS$19+$CZ$13/$CS$19^3+$DB$13/$CS$19^4+$DD$13/$CS$19^5)*DE20 -> -0.066759338 | DG20: =($DF$13+$DH$13/$CS$19+$CV$14/$CS$19^2)*DE20^2 -> 0.0039590009 | DH20: =$CX$14*($DH$13/$CS$19+$CV$14/$CS$19^2)*DE20^5 -> -3.2671421e-06 | DI20: =$CZ$14*(1+$DB$14*DE20^2)*DE20^2/$CS$19^3 -> 0.003177507 | DJ20: =EXP(-$DB$14*DE20^2) -> 0.98340407 | DK20: =1+DF20+DG20-DH20+DI20*DJ20 -> 0.9403277 | DL20: =DK20-DD20 -> 0.090327704 | DM20: =(DL20-DC20)/(DD20-CU20) -> -0.93483416 | DN20: =CU20-DC20/DM20 -> 0.94662431 | DO20: =DD20 -> 0.85 | DP20: =0.27*CT20/DO20/$CS$19 -> 0.1523518 | DQ20: =($CV$13+$CX$13/$CS$19+$CZ$13/$CS$19^3+$DB$13/$CS$19^4+$DD$13/$CS$19^5)*DP20 -> -0.066759338 | DR20: =($DF$13+$DH$13/$CS$19+$CV$14/$CS$19^2)*DP20^2 -> 0.0039590009 | DS20: =$CX$14*($DH$13/$CS$19+$CV$14/$CS$19^2)*DP20^5 -> -3.2671421e-06 | DT20: =$CZ$14*(1+$DB$14*DP20^2)*(DP20^2/$CS$19^3) -> 0.003177507 | DU20: =EXP(-$DB$14*DP20^2) -> 0.98340407 | DV20: =1+DQ20+DR20-DS20+DT20*DU20 -> 0.9403277 | DW20: =DV20-DO20 -> 0.090327704 | DX20: =DN20 -> 0.94662431 | DY20: =0.27*CT20/DX20/$CS$19 -> 0.13680087 | DZ20: =($CV$13+$CX$13/$CS$19+$CZ$13/$CS$19^3+$DB$13/$CS$19^4+$DD$13/$CS$19^5)*DY20 -> -0.059945045 | EA20: =($DF$13+$DH$13/$CS$19+$CV$14/$CS$19^2)*DY20^2 -> 0.0031920387 | EB20: =$CX$14*($DH$13/$CS$19+$CV$14/$CS$19^2)*DY20^5 -> -1.907104e-06 | EC20: =$CZ$14*(1+$DB$14*DY20^2)*DY20^2/$CS$19^3 -> 0.0025537714 | ED20: =EXP(-$DB$14*DY20^2) -> 0.98659749 | EE20: =1+DZ20+EA20-EB20+EC20*ED20 -> 0.94576845 | EF20: =EE20-DX20 -> -0.00085586328 | EG20: =(EF20-DW20)/(DX20-DO20) -> -0.9436918 | EH20: =DO20-DW20/EG20 -> 0.94571738 | EL20: =K20 -> 530.33301 | EV20: =(EL20*$EP$19)/(DN20*10.73*$EK$19) -> 1.5857746 | EW20: =EV20/67.0176 -> 0.023662061 | EX20: =EXP($ET$19*EW20^$EU$19) -> 1.0436397 | EY20: =$ES$19*10^-4*EX20 -> 0.013087439
C21: =E20 -> 577.16051 | D21: 515 | E21: =CL21 -> 608.88497 | F21: =D21-E21 -> -93.884966 | G21: =AVERAGE(C21,D21) -> 546.08026 | I21: =Sheet10!K20 -> 596.3076 | K21: =G21 -> 546.08026 | O21: =(($O$8*K21^1.0937)/27.64)*10^(11.172*$N$19) -> 80.909525 | R21: =$W$6*EXP($W$9*(1697-G21)) -> 1.2303527 | S21: =0.0283*AT21*($M$19)/K21 -> 0.030337948 | T21: =$O$3*($O$4+R21) -> 123.03527 | U21: =T21*5.615 -> 690.84304 | V21: =IF($O$5>0,S21*($O$10-O21)*$O$3,0) -> 512.9858 | W21: =$Y$15+$Z$14*(O21-$X$15) -> 0.80190905 | X21: =$W$7 -> 48.33 | Y21: =R21/$W$6 -> 1.0252939 | Z21: =X21*Y21 -> 49.552455 | AA21: =($O$4*$S$6)+(R21*Z21) -> 60.966996 | AB21: =$O$4+R21 -> 1.2303527 | AC21: =AA21/AB21 -> 49.552455 | AH21: =10.715*(O21+100)^-0.515 -> 0.7368847 | AI21: =5.44*(O21+150)^-0.338 -> 0.8644812 | AJ21: =AH21*$AG$19^AI21 -> 3.113246 | AK21: =(($O$4*$S$6)/($O$4*$S$6+R21*Z21))*$S$7 -> 0 | AL21: =((R21*Z21)/($O$4*$S$6+R21*Z21))*AJ21 -> 3.113246 | AM21: =AK21+AL21 -> 3.113246 | AN21: =(($O$4*$S$6)/($O$4*$S$6+R21*Z21))*$S$8 -> 0 | AO21: =((R21*Z21)/($O$4*$S$6+R21*Z21))*$S$4 -> 30 | AP21: =AN21+AO21 -> 30 | AR21: =CT21 -> 0.81871103 | AT21: =EH21 -> 0.9442012 | AV21: =(U21)*(1/86400)/$S$10 -> 0.36650276 | AW21: =(V21)*(1/86400)/$S$10 -> 0.27214678 | AX21: =AV21+AW21 -> 0.63864954 | AY21: =AV21/AX21 -> 0.57387148 | AZ21: =1-AY21 -> 0.42612852 | BA21: =1.071-(0.2218*((AX21^2)/($S$9))) -> 0.5282023 | BB21: =IF(BA21<0.13,0.13,BA21) -> 0.5282023 | BC21: =1.938*AV21*(AC21/AP21)^(1/4) -> 0.80522454 | BD21: =1.938*AW21*(AC21/AP21)^(1/4) -> 0.59791983 | BE21: =120.872*$S$9*SQRT(AC21/AP21) -> 25.890856 | BF21: =0.15726*AM21*(1/(AC21*AP21^3))^(1/4) -> 0.014395424 | BG21: =0.0019+0.0322*BF21-0.6642*BF21^2+4.9951*BF21^3 -> 0.0022407927 | BH21: =1-10.0147*BF21+33.8696*BF21^2+277.2817*BF21^3 -> 0.86368005 | BI21: =BG21/BH21 -> 0.0025944709 | BJ21: =BC21*($K$19^0.1)*BI21 -> 0.0039005463 | BK21: =(BD21^0.575)*(14.7^0.1)*BE21 -> 25.202745 | BL21: =BJ21/BK21 -> 0.00015476672 | BM21: =(0.0047+1123.32*BL21+729489.64*BL21^2) -> 0.19602583 | BN21: =(1+1097.1566*BL21+722153.97*BL21^2) -> 1.1871009 | BO21: =SQRT(BM21/BN21) -> 0.40636176 | BP21: =(BD21*BF21^0.38)/BE21^2.14 -> 0.00011288466 | BQ21: =1.0886-69.9473*BP21+2334.3497*BP21^2-12896.683*BP21^3 -> 1.0807338 | BR21: =1-53.4401*BP21+1517.9369*BP21^2-8419.8115*BP21^3 -> 0.99398676 | BS21: =BQ21/BR21 -> 1.0872718 | BT21: =IF(V21<=0,1,(BO21*BS21)) -> 0.44182567 | BU21: =IF(V21>1,BO21*BS21,1) -> 0.44182567 | BV21: =IF($O$5=0,1,BU21) -> 0.44182567 | BW21: =AC21*AV21 -> 18.161111 | BX21: =EV21*AW21 -> 0.44509425 | BY21: =$S$10*(BW21+BX21)*86400 -> 35071.953 | BZ21: =(AM21^BT21)*EY21^(1-BT21) -> 0.14696357 | CA21: =2.2*10^-2*BY21/BZ21/$S$9 -> 31500.99 | CB21: =$CC$16/3.7065 -> 0.00016187778 | CC21: =5.0452/CA21 -> 0.00016016005 | CD21: =LOG(($CC$16^1.1098/2.8257)+(7.149/CA21)^0.8981) -> -3.202265 | CE21: =-4*LOG(CB21-(CC21*CD21)) -> 12.683422 | CF21: =1/CE21^2 -> 0.0062162311 | CG21: =BT21*AC21+(1-BT21)*EV21 -> 22.806437 | CH21: =CF21*BY21^2/($S$9)^5/CG21 -> 2.607029e+09 | CI21: =(1/144)*(CG21+(CH21/74130000000)) -> 0.15862226 | CJ21: =CI21*$CJ$15 -> 31.724452 | CK21: =CK20+200 -> 600 | CL21: =C21+CJ21 -> 608.88497 | CT21: =K21/$CR$19 -> 0.81871103 | CU21: 0.8 | CV21: =0.27*CT21/CU21/$CS$19 -> 0.16668032 | CW21: =($CV$13+$CX$13/$CS$19+$CZ$13/$CS$19^3+$DB$13/$CS$19^4+$DD$13/$CS$19^5)*CV21 -> -0.073037984 | CX21: =($DF$13+$DH$13/$CS$19+$CV$14/$CS$19^2)*CV21^2 -> 0.0047386989 | CY21: =$CX$14*($DH$13/$CS$19+$CV$14/$CS$19^2)*CV21^5 -> -5.1209649e-06 | CZ21: =$CZ$14*(1+$DB$14*CV21^2)*(CV21^2/$CS$19^3) -> 0.003815624 | DA21: =EXP(-$DB$14*CV21^2) -> 0.98016823 | DB21: =1+CW21+CX21-CY21+CZ21*DA21 -> 0.93544579 | DC21: =DB21-CU21 -> 0.13544579 | DD21: 0.85 | DE21: =0.27*CT21/DD21/$CS$19 -> 0.1568756 | DF21: =($CV$13+$CX$13/$CS$19+$CZ$13/$CS$19^3+$DB$13/$CS$19^4+$DD$13/$CS$19^5)*DE21 -> -0.068741632 | DG21: =($DF$13+$DH$13/$CS$19+$CV$14/$CS$19^2)*DE21^2 -> 0.0041976018 | DH21: =$CX$14*($DH$13/$CS$19+$CV$14/$CS$19^2)*DE21^5 -> -3.7818744e-06 | DI21: =$CZ$14*(1+$DB$14*DE21^2)*DE21^2/$CS$19^3 -> 0.0033723508 | DJ21: =EXP(-$DB$14*DE21^2) -> 0.98241272 | DK21: =1+DF21+DG21-DH21+DI21*DJ21 -> 0.93877279 | DL21: =DK21-DD21 -> 0.088772792 | DM21: =(DL21-DC21)/(DD21-CU21) -> -0.93345995 | DN21: =CU21-DC21/DM21 -> 0.94510081 | DO21: =DD21 -> 0.85 | DP21: =0.27*CT21/DO21/$CS$19 -> 0.1568756 | DQ21: =($CV$13+$CX$13/$CS$19+$CZ$13/$CS$19^3+$DB$13/$CS$19^4+$DD$13/$CS$19^5)*DP21 -> -0.068741632 | DR21: =($DF$13+$DH$13/$CS$19+$CV$14/$CS$19^2)*DP21^2 -> 0.0041976018 | DS21: =$CX$14*($DH$13/$CS$19+$CV$14/$CS$19^2)*DP21^5 -> -3.7818744e-06 | DT21: =$CZ$14*(1+$DB$14*DP21^2)*(DP21^2/$CS$19^3) -> 0.0033723508 | DU21: =EXP(-$DB$14*DP21^2) -> 0.98241272 | DV21: =1+DQ21+DR21-DS21+DT21*DU21 -> 0.93877279 | DW21: =DV21-DO21 -> 0.088772792 | DX21: =DN21 -> 0.94510081 | DY21: =0.27*CT21/DX21/$CS$19 -> 0.14108998 | DZ21: =($CV$13+$CX$13/$CS$19+$CZ$13/$CS$19^3+$DB$13/$CS$19^4+$DD$13/$CS$19^5)*DY21 -> -0.061824502 | EA21: =($DF$13+$DH$13/$CS$19+$CV$14/$CS$19^2)*DY21^2 -> 0.0033953365 | EB21: =$CX$14*($DH$13/$CS$19+$CV$14/$CS$19^2)*DY21^5 -> -2.2254153e-06 | EC21: =$CZ$14*(1+$DB$14*DY21^2)*DY21^2/$CS$19^3 -> 0.0027187219 | ED21: =EXP(-$DB$14*DY21^2) -> 0.98575 | EE21: =1+DZ21+EA21-EB21+EC21*ED21 -> 0.94425304 | EF21: =EE21-DX21 -> -0.00084776544 | EG21: =(EF21-DW21)/(DX21-DO21) -> -0.94237433 | EH21: =DO21-DW21/EG21 -> 0.9442012 | EL21: =K21 -> 546.08026 | EV21: =(EL21*$EP$19)/(DN21*10.73*$EK$19) -> 1.6354933 | EW21: =EV21/67.0176 -> 0.024403938 | EX21: =EXP($ET$19*EW21^$EU$19) -> 1.0454439 | EY21: =$ES$19*10^-4*EX21 -> 0.013110064
C22: =E21 -> 608.88497 | D22: 515.1 | E22: =CL22 -> 640.94112 | F22: =D22-E22 -> -125.84112 | G22: =AVERAGE(C22,D22) -> 561.99248 | I22: =Sheet10!K21 -> 629.76327 | K22: =G22 -> 561.99248 | O22: =(($O$8*K22^1.0937)/27.64)*10^(11.172*$N$19) -> 83.491546 | R22: =$W$6*EXP($W$9*(1697-G22)) -> 1.2299279 | S22: =0.0283*AT22*($M$19)/K22 -> 0.029431345 | T22: =$O$3*($O$4+R22) -> 122.99279 | U22: =T22*5.615 -> 690.60449 | V22: =IF($O$5>0,S22*($O$10-O22)*$O$3,0) -> 490.05677 | W22: =$Y$15+$Z$14*(O22-$X$15) -> 0.80165085 | X22: =$W$7 -> 48.33 | Y22: =R22/$W$6 -> 1.0249399 | Z22: =X22*Y22 -> 49.535345 | AA22: =($O$4*$S$6)+(R22*Z22) -> 60.9249 | AB22: =$O$4+R22 -> 1.2299279 | AC22: =AA22/AB22 -> 49.535345 | AH22: =10.715*(O22+100)^-0.515 -> 0.73152623 | AI22: =5.44*(O22+150)^-0.338 -> 0.86123813 | AJ22: =AH22*$AG$19^AI22 -> 3.0739449 | AK22: =(($O$4*$S$6)/($O$4*$S$6+R22*Z22))*$S$7 -> 0 | AL22: =((R22*Z22)/($O$4*$S$6+R22*Z22))*AJ22 -> 3.0739449 | AM22: =AK22+AL22 -> 3.0739449 | AN22: =(($O$4*$S$6)/($O$4*$S$6+R22*Z22))*$S$8 -> 0 | AO22: =((R22*Z22)/($O$4*$S$6+R22*Z22))*$S$4 -> 30 | AP22: =AN22+AO22 -> 30 | AR22: =CT22 -> 0.84256744 | AT22: =EH22 -> 0.94267608 | AV22: =(U22)*(1/86400)/$S$10 -> 0.36637621 | AW22: =(V22)*(1/86400)/$S$10 -> 0.25998259 | AX22: =AV22+AW22 -> 0.62635879 | AY22: =AV22/AX22 -> 0.58493025 | AZ22: =1-AY22 -> 0.41506975 | BA22: =1.071-(0.2218*((AX22^2)/($S$9))) -> 0.54889344 | BB22: =IF(BA22<0.13,0.13,BA22) -> 0.54889344 | BC22: =1.938*AV22*(AC22/AP22)^(1/4) -> 0.804877 | BD22: =1.938*AW22*(AC22/AP22)^(1/4) -> 0.57114518 | BE22: =120.872*$S$9*SQRT(AC22/AP22) -> 25.886386 | BF22: =0.15726*AM22*(1/(AC22*AP22^3))^(1/4) -> 0.014214926 | BG22: =0.0019+0.0322*BF22-0.6642*BF22^2+4.9951*BF22^3 -> 0.0022378572 | BH22: =1-10.0147*BF22+33.8696*BF22^2+277.2817*BF22^3 -> 0.86528205 | BI22: =BG22/BH22 -> 0.0025862748 | BJ22: =BC22*($K$19^0.1)*BI22 -> 0.0038865461 | BK22: =(BD22^0.575)*(14.7^0.1)*BE22 -> 24.543269 | BL22: =BJ22/BK22 -> 0.00015835487 | BM22: =(0.0047+1123.32*BL22+729489.64*BL22^2) -> 0.20087607 | BN22: =(1+1097.1566*BL22+722153.97*BL22^2) -> 1.191849 | BO22: =SQRT(BM22/BN22) -> 0.41053811 | BP22: =(BD22*BF22^0.38)/BE22^2.14 -> 0.0001073536 | BQ22: =1.0886-69.9473*BP22+2334.3497*BP22^2-12896.683*BP22^3 -> 1.0811178 | BR22: =1-53.4401*BP22+1517.9369*BP22^2-8419.8115*BP22^3 -> 0.9942805 | BS22: =BQ22/BR22 -> 1.0873368 | BT22: =IF(V22<=0,1,(BO22*BS22)) -> 0.4463932 | BU22: =IF(V22>1,BO22*BS22,1) -> 0.4463932 | BV22: =IF($O$5=0,1,BU22) -> 0.4463932 | BW22: =AC22*AV22 -> 18.148572 | BX22: =EV22*AW22 -> 0.43830094 | BY22: =$S$10*(BW22+BX22)*86400 -> 35035.511 | BZ22: =(AM22^BT22)*EY22^(1-BT22) -> 0.14997609 | CA22: =2.2*10^-2*BY22/BZ22/$S$9 -> 30836.166 | CB22: =$CC$16/3.7065 -> 0.00016187778 | CC22: =5.0452/CA22 -> 0.00016361308 | CD22: =LOG(($CC$16^1.1098/2.8257)+(7.149/CA22)^0.8981) -> -3.1951814 | CE22: =-4*LOG(CB22-(CC22*CD22)) -> 12.658122 | CF22: =1/CE22^2 -> 0.006241104 | CG22: =BT22*AC22+(1-BT22)*EV22 -> 23.045559 | CH22: =CF22*BY22^2/($S$9)^5/CG22 -> 2.5849214e+09 | CI22: =(1/144)*(CG22+(CH22/74130000000)) -> 0.16028076 | CJ22: =CI22*$CJ$15 -> 32.056151 | CK22: =CK21+200 -> 800 | CL22: =C22+CJ22 -> 640.94112 | CT22: =K22/$CR$19 -> 0.84256744 | CU22: 0.8 | CV22: =0.27*CT22/CU22/$CS$19 -> 0.17153722 | CW22: =($CV$13+$CX$13/$CS$19+$CZ$13/$CS$19^3+$DB$13/$CS$19^4+$DD$13/$CS$19^5)*CV22 -> -0.075166236 | CX22: =($DF$13+$DH$13/$CS$19+$CV$14/$CS$19^2)*CV22^2 -> 0.0050188842 | CY22: =$CX$14*($DH$13/$CS$19+$CV$14/$CS$19^2)*CV22^5 -> -5.9118303e-06 | CZ22: =$CZ$14*(1+$DB$14*CV22^2)*(CV22^2/$CS$19^3) -> 0.0040459229 | DA22: =EXP(-$DB$14*CV22^2) -> 0.97900803 | DB22: =1+CW22+CX22-CY22+CZ22*DA22 -> 0.93381955 | DC22: =DB22-CU22 -> 0.13381955 | DD22: 0.85 | DE22: =0.27*CT22/DD22/$CS$19 -> 0.16144679 | DF22: =($CV$13+$CX$13/$CS$19+$CZ$13/$CS$19^3+$DB$13/$CS$19^4+$DD$13/$CS$19^5)*DE22 -> -0.070744693 | DG22: =($DF$13+$DH$13/$CS$19+$CV$14/$CS$19^2)*DE22^2 -> 0.0044457936 | DH22: =$CX$14*($DH$13/$CS$19+$CV$14/$CS$19^2)*DE22^5 -> -4.365935e-06 | DI22: =$CZ$14*(1+$DB$14*DE22^2)*DE22^2/$CS$19^3 -> 0.0035754299 | DJ22: =EXP(-$DB$14*DE22^2) -> 0.98138257 | DK22: =1+DF22+DG22-DH22+DI22*DJ22 -> 0.93721433 | DL22: =DK22-DD22 -> 0.087214331 | DM22: =(DL22-DC22)/(DD22-CU22) -> -0.93210439 | DN22: =CU22-DC22/DM22 -> 0.94356713 | DO22: =DD22 -> 0.85 | DP22: =0.27*CT22/DO22/$CS$19 -> 0.16144679 | DQ22: =($CV$13+$CX$13/$CS$19+$CZ$13/$CS$19^3+$DB$13/$CS$19^4+$DD$13/$CS$19^5)*DP22 -> -0.070744693 | DR22: =($DF$13+$DH$13/$CS$19+$CV$14/$CS$19^2)*DP22^2 -> 0.0044457936 | DS22: =$CX$14*($DH$13/$CS$19+$CV$14/$CS$19^2)*DP22^5 -> -4.365935e-06 | DT22: =$CZ$14*(1+$DB$14*DP22^2)*(DP22^2/$CS$19^3) -> 0.0035754299 | DU22: =EXP(-$DB$14*DP22^2) -> 0.98138257 | DV22: =1+DQ22+DR22-DS22+DT22*DU22 -> 0.93721433 | DW22: =DV22-DO22 -> 0.087214331 | DX22: =DN22 -> 0.94356713 | DY22: =0.27*CT22/DX22/$CS$19 -> 0.14543721 | DZ22: =($CV$13+$CX$13/$CS$19+$CZ$13/$CS$19^3+$DB$13/$CS$19^4+$DD$13/$CS$19^5)*DY22 -> -0.063729424 | EA22: =($DF$13+$DH$13/$CS$19+$CV$14/$CS$19^2)*DY22^2 -> 0.0036077924 | EB22: =$CX$14*($DH$13/$CS$19+$CV$14/$CS$19^2)*DY22^5 -> -2.5900484e-06 | EC22: =$CZ$14*(1+$DB$14*DY22^2)*DY22^2/$CS$19^3 -> 0.0028913978 | ED22: =EXP(-$DB$14*DY22^2) -> 0.98486512 | EE22: =1+DZ22+EA22-EB22+EC22*ED22 -> 0.9427286 | EF22: =EE22-DX22 -> -0.0008385324 | EG22: =(EF22-DW22)/(DX22-DO22) -> -0.94106622 | EH22: =DO22-DW22/EG22 -> 0.94267608 | EL22: =K22 -> 561.99248 | EV22: =(EL22*$EP$19)/(DN22*10.73*$EK$19) -> 1.6858858 | EW22: =EV22/67.0176 -> 0.025155866 | EX22: =EXP($ET$19*EW22^$EU$19) -> 1.0472917 | EY22: =$ES$19*10^-4*EX22 -> 0.013133236
C23: =E22 -> 640.94112 | D23: 515.2 | E23: =CL23 -> 673.331 | F23: =D23-E23 -> -158.131 | G23: =AVERAGE(C23,D23) -> 578.07056 | I23: =Sheet10!K22 -> 663.91525 | K23: =G23 -> 578.07056 | O23: =(($O$8*K23^1.0937)/27.64)*10^(11.172*$N$19) -> 86.107445 | R23: =$W$6*EXP($W$9*(1697-G23)) -> 1.2294987 | S23: =0.0283*AT23*($M$19)/K23 -> 0.028566206 | T23: =$O$3*($O$4+R23) -> 122.94987 | U23: =T23*5.615 -> 690.36354 | V23: =IF($O$5>0,S23*($O$10-O23)*$O$3,0) -> 468.17885 | W23: =$Y$15+$Z$14*(O23-$X$15) -> 0.80138926 | X23: =$W$7 -> 48.33 | Y23: =R23/$W$6 -> 1.0245823 | Z23: =X23*Y23 -> 49.518062 | AA23: =($O$4*$S$6)+(R23*Z23) -> 60.882395 | AB23: =$O$4+R23 -> 1.2294987 | AC23: =AA23/AB23 -> 49.518062 | AH23: =10.715*(O23+100)^-0.515 -> 0.72621271 | AI23: =5.44*(O23+150)^-0.338 -> 0.85800107 | AJ23: =AH23*$AG$19^AI23 -> 3.0351954 | AK23: =(($O$4*$S$6)/($O$4*$S$6+R23*Z23))*$S$7 -> 0 | AL23: =((R23*Z23)/($O$4*$S$6+R23*Z23))*AJ23 -> 3.0351954 | AM23: =AK23+AL23 -> 3.0351954 | AN23: =(($O$4*$S$6)/($O$4*$S$6+R23*Z23))*$S$8 -> 0 | AO23: =((R23*Z23)/($O$4*$S$6+R23*Z23))*$S$4 -> 30 | AP23: =AN23+AO23 -> 30 | AR23: =CT23 -> 0.8666725 | AT23: =EH23 -> 0.94114229 | AV23: =(U23)*(1/86400)/$S$10 -> 0.36624838 | AW23: =(V23)*(1/86400)/$S$10 -> 0.24837601 | AX23: =AV23+AW23 -> 0.61462439 | AY23: =AV23/AX23 -> 0.59588976 | AZ23: =1-AY23 -> 0.40411024 | BA23: =1.071-(0.2218*((AX23^2)/($S$9))) -> 0.56827281 | BB23: =IF(BA23<0.13,0.13,BA23) -> 0.56827281 | BC23: =1.938*AV23*(AC23/AP23)^(1/4) -> 0.80452599 | BD23: =1.938*AW23*(AC23/AP23)^(1/4) -> 0.54559957 | BE23: =120.872*$S$9*SQRT(AC23/AP23) -> 25.88187 | BF23: =0.15726*AM23*(1/(AC23*AP23^3))^(1/4) -> 0.01403696 | BG23: =0.0019+0.0322*BF23-0.6642*BF23^2+4.9951*BF23^3 -> 0.002234934 | BH23: =1-10.0147*BF23+33.8696*BF23^2+277.2817*BF23^3 -> 0.8668645 | BI23: =BG23/BH23 -> 0.0025781815 | BJ23: =BC23*($K$19^0.1)*BI23 -> 0.0038726942 | BK23: =(BD23^0.575)*(14.7^0.1)*BE23 -> 23.901763 | BL23: =BJ23/BK23 -> 0.00016202546 | BM23: =(0.0047+1123.32*BL23+729489.64*BL23^2) -> 0.20585719 | BN23: =(1+1097.1566*BL23+722153.97*BL23^2) -> 1.1967255 | BO23: =SQRT(BM23/BN23) -> 0.41474938 | BP23: =(BD23*BF23^0.38)/BE23^2.14 -> 0.00010210032 | BQ23: =1.0886-69.9473*BP23+2334.3497*BP23^2-12896.683*BP23^3 -> 1.0814827 | BR23: =1-53.4401*BP23+1517.9369*BP23^2-8419.8115*BP23^3 -> 0.99455956 | BS23: =BQ23/BR23 -> 1.0873986 | BT23: =IF(V23<=0,1,(BO23*BS23)) -> 0.4509979 | BU23: =IF(V23>1,BO23*BS23,1) -> 0.4509979 | BV23: =IF($O$5=0,1,BU23) -> 0.4509979 | BW23: =AC23*AV23 -> 18.13591 | BX23: =EV23*AW23 -> 0.43141891 | BY23: =$S$10*(BW23+BX23)*86400 -> 34998.672 | BZ23: =(AM23^BT23)*EY23^(1-BT23) -> 0.15306564 | CA23: =2.2*10^-2*BY23/BZ23/$S$9 -> 30181.984 | CB23: =$CC$16/3.7065 -> 0.00016187778 | CC23: =5.0452/CA23 -> 0.00016715932 | CD23: =LOG(($CC$16^1.1098/2.8257)+(7.149/CA23)^0.8981) -> -3.1880403 | CE23: =-4*LOG(CB23-(CC23*CD23)) -> 12.63259 | CF23: =1/CE23^2 -> 0.0062663583 | CG23: =BT23*AC23+(1-BT23)*EV23 -> 23.286136 | CH23: =CF23*BY23^2/($S$9)^5/CG23 -> 2.5631686e+09 | CI23: =(1/144)*(CG23+(CH23/74130000000)) -> 0.16194939 | CJ23: =CI23*$CJ$15 -> 32.389879 | CK23: =CK22+200 -> 1000 | CL23: =C23+CJ23 -> 673.331 | CT23: =K23/$CR$19 -> 0.8666725 | CU23: 0.8 | CV23: =0.27*CT23/CU23/$CS$19 -> 0.17644474 | CW23: =($CV$13+$CX$13/$CS$19+$CZ$13/$CS$19^3+$DB$13/$CS$19^4+$DD$13/$CS$19^5)*CV23 -> -0.077316672 | CX23: =($DF$13+$DH$13/$CS$19+$CV$14/$CS$19^2)*CV23^2 -> 0.0053101632 | CY23: =$CX$14*($DH$13/$CS$19+$CV$14/$CS$19^2)*CV23^5 -> -6.807281e-06 | CZ23: =$CZ$14*(1+$DB$14*CV23^2)*(CV23^2/$CS$19^3) -> 0.0042858958 | DA23: =EXP(-$DB$14*CV23^2) -> 0.97780334 | DB23: =1+CW23+CX23-CY23+CZ23*DA23 -> 0.93219106 | DC23: =DB23-CU23 -> 0.13219106 | DD23: 0.85 | DE23: =0.27*CT23/DD23/$CS$19 -> 0.16606563 | DF23: =($CV$13+$CX$13/$CS$19+$CZ$13/$CS$19^3+$DB$13/$CS$19^4+$DD$13/$CS$19^5)*DE23 -> -0.072768632 | DG23: =($DF$13+$DH$13/$CS$19+$CV$14/$CS$19^2)*DE23^2 -> 0.0047038123 | DH23: =$CX$14*($DH$13/$CS$19+$CV$14/$CS$19^2)*DE23^5 -> -5.0272327e-06 | DI23: =$CZ$14*(1+$DB$14*DE23^2)*DE23^2/$CS$19^3 -> 0.0037869856 | DJ23: =EXP(-$DB$14*DE23^2) -> 0.98031278 | DK23: =1+DF23+DG23-DH23+DI23*DJ23 -> 0.93565264 | DL23: =DK23-DD23 -> 0.085652638 | DM23: =(DL23-DC23)/(DD23-CU23) -> -0.93076848 | DN23: =CU23-DC23/DM23 -> 0.94202357 | DO23: =DD23 -> 0.85 | DP23: =0.27*CT23/DO23/$CS$19 -> 0.16606563 | DQ23: =($CV$13+$CX$13/$CS$19+$CZ$13/$CS$19^3+$DB$13/$CS$19^4+$DD$13/$CS$19^5)*DP23 -> -0.072768632 | DR23: =($DF$13+$DH$13/$CS$19+$CV$14/$CS$19^2)*DP23^2 -> 0.0047038123 | DS23: =$CX$14*($DH$13/$CS$19+$CV$14/$CS$19^2)*DP23^5 -> -5.0272327e-06 | DT23: =$CZ$14*(1+$DB$14*DP23^2)*(DP23^2/$CS$19^3) -> 0.0037869856 | DU23: =EXP(-$DB$14*DP23^2) -> 0.98031278 | DV23: =1+DQ23+DR23-DS23+DT23*DU23 -> 0.93565264 | DW23: =DV23-DO23 -> 0.085652638 | DX23: =DN23 -> 0.94202357 | DY23: =0.27*CT23/DX23/$CS$19 -> 0.14984316 | DZ23: =($CV$13+$CX$13/$CS$19+$CZ$13/$CS$19^3+$DB$13/$CS$19^4+$DD$13/$CS$19^5)*DY23 -> -0.065660074 | EA23: =($DF$13+$DH$13/$CS$19+$CV$14/$CS$19^2)*DY23^2 -> 0.003829696 | EB23: =$CX$14*($DH$13/$CS$19+$CV$14/$CS$19^2)*DY23^5 -> -3.0068708e-06 | EC23: =$CZ$14*(1+$DB$14*DY23^2)*DY23^2/$CS$19^3 -> 0.003072074 | ED23: =EXP(-$DB$14*DY23^2) -> 0.98394174 | EE23: =1+DZ23+EA23-EB23+EC23*ED23 -> 0.94119537 | EF23: =EE23-DX23 -> -0.00082819836 | EG23: =(EF23-DW23)/(DX23-DO23) -> -0.93976833 | EH23: =DO23-DW23/EG23 -> 0.94114229 | EL23: =K23 -> 578.07056 | EV23: =(EL23*$EP$19)/(DN23*10.73*$EK$19) -> 1.7369588 | EW23: =EV23/67.0176 -> 0.02591795 | EX23: =EXP($ET$19*EW23^$EU$19) -> 1.049184 | EY23: =$ES$19*10^-4*EX23 -> 0.013156965
C24: =E23 -> 673.331 | D24: 515.3 | E24: =CL24 -> 706.05692 | F24: =D24-E24 -> -190.75692 | G24: =AVERAGE(C24,D24) -> 594.3155 | I24: =Sheet10!K23 -> 698.77943 | K24: =G24 -> 594.3155 | O24: =(($O$8*K24^1.0937)/27.64)*10^(11.172*$N$19) -> 88.757426 | R24: =$W$6*EXP($W$9*(1697-G24)) -> 1.2290653 | S24: =0.0283*AT24*($M$19)/K24 -> 0.02773985 | T24: =$O$3*($O$4+R24) -> 122.90653 | U24: =T24*5.615 -> 690.12018 | V24: =IF($O$5>0,S24*($O$10-O24)*$O$3,0) -> 447.28449 | W24: =$Y$15+$Z$14*(O24-$X$15) -> 0.80112426 | X24: =$W$7 -> 48.33 | Y24: =R24/$W$6 -> 1.0242211 | Z24: =X24*Y24 -> 49.500606 | AA24: =($O$4*$S$6)+(R24*Z24) -> 60.839479 | AB24: =$O$4+R24 -> 1.2290653 | AC24: =AA24/AB24 -> 49.500606 | AH24: =10.715*(O24+100)^-0.515 -> 0.7209441 | AI24: =5.44*(O24+150)^-0.338 -> 0.85477039 | AJ24: =AH24*$AG$19^AI24 -> 2.9969925 | AK24: =(($O$4*$S$6)/($O$4*$S$6+R24*Z24))*$S$7 -> 0 | AL24: =((R24*Z24)/($O$4*$S$6+R24*Z24))*AJ24 -> 2.9969925 | AM24: =AK24+AL24 -> 2.9969925 | AN24: =(($O$4*$S$6)/($O$4*$S$6+R24*Z24))*$S$8 -> 0 | AO24: =((R24*Z24)/($O$4*$S$6+R24*Z24))*$S$4 -> 30 | AP24: =AN24+AO24 -> 30 | AR24: =CT24 -> 0.89102773 | AT24: =EH24 -> 0.93960008 | AV24: =(U24)*(1/86400)/$S$10 -> 0.36611927 | AW24: =(V24)*(1/86400)/$S$10 -> 0.23729124 | AX24: =AV24+AW24 -> 0.60341051 | AY24: =AV24/AX24 -> 0.60674991 | AZ24: =1-AY24 -> 0.39325009 | BA24: =1.071-(0.2218*((AX24^2)/($S$9))) -> 0.58645008 | BB24: =IF(BA24<0.13,0.13,BA24) -> 0.58645008 | BC24: =1.938*AV24*(AC24/AP24)^(1/4) -> 0.8041715 | BD24: =1.938*AW24*(AC24/AP24)^(1/4) -> 0.52120406 | BE24: =120.872*$S$9*SQRT(AC24/AP24) -> 25.877308 | BF24: =0.15726*AM24*(1/(AC24*AP24^3))^(1/4) -> 0.013861504 | BG24: =0.0019+0.0322*BF24-0.6642*BF24^2+4.9951*BF24^3 -> 0.002232024 | BH24: =1-10.0147*BF24+33.8696*BF24^2+277.2817*BF24^3 -> 0.86842745 | BI24: =BG24/BH24 -> 0.0025701905 | BJ24: =BC24*($K$19^0.1)*BI24 -> 0.0038589898 | BK24: =(BD24^0.575)*(14.7^0.1)*BE24 -> 23.277176 | BL24: =BJ24/BK24 -> 0.00016578427 | BM24: =(0.0047+1123.32*BL24+729489.64*BL24^2) -> 0.21097839 | BN24: =(1+1097.1566*BL24+722153.97*BL24^2) -> 1.2017393 | BO24: =SQRT(BM24/BN24) -> 0.41899984 | BP24: =(BD24*BF24^0.38)/BE24^2.14 -> 9.7106628e-05 | BQ24: =1.0886-69.9473*BP24+2334.3497*BP24^2-12896.683*BP24^3 -> 1.0818297 | BR24: =1-53.4401*BP24+1517.9369*BP24^2-8419.8115*BP24^3 -> 0.99482492 | BS24: =BQ24/BR24 -> 1.0874573 | BT24: =IF(V24<=0,1,(BO24*BS24)) -> 0.45564445 | BU24: =IF(V24>1,BO24*BS24,1) -> 0.45564445 | BV24: =IF($O$5=0,1,BU24) -> 0.45564445 | BW24: =AC24*AV24 -> 18.123126 | BX24: =EV24*AW24 -> 0.42444757 | BY24: =$S$10*(BW24+BX24)*86400 -> 34961.434 | BZ24: =(AM24^BT24)*EY24^(1-BT24) -> 0.15623823 | CA24: =2.2*10^-2*BY24/BZ24/$S$9 -> 29537.644 | CB24: =$CC$16/3.7065 -> 0.00016187778 | CC24: =5.0452/CA24 -> 0.00017080577 | CD24: =LOG(($CC$16^1.1098/2.8257)+(7.149/CA24)^0.8981) -> -3.1808336 | CE24: =-4*LOG(CB24-(CC24*CD24)) -> 12.606794 | CF24: =1/CE24^2 -> 0.0062920287 | CG24: =BT24*AC24+(1-BT24)*EV24 -> 23.528376 | CH24: =CF24*BY24^2/($S$9)^5/CG24 -> 2.5417537e+09 | CI24: =(1/144)*(CG24+(CH24/74130000000)) -> 0.16362961 | CJ24: =CI24*$CJ$15 -> 32.725922 | CK24: =CK23+200 -> 1200 | CL24: =C24+CJ24 -> 706.05692 | CT24: =K24/$CR$19 -> 0.89102773 | CU24: 0.8 | CV24: =0.27*CT24/CU24/$CS$19 -> 0.18140319 | CW24: =($CV$13+$CX$13/$CS$19+$CZ$13/$CS$19^3+$DB$13/$CS$19^4+$DD$13/$CS$19^5)*CV24 -> -0.079489425 | CX24: =($DF$13+$DH$13/$CS$19+$CV$14/$CS$19^2)*CV24^2 -> 0.0056128091 | CY24: =$CX$14*($DH$13/$CS$19+$CV$14/$CS$19^2)*CV24^5 -> -7.8190628e-06 | CZ24: =$CZ$14*(1+$DB$14*CV24^2)*(CV24^2/$CS$19^3) -> 0.0045358332 | DA24: =EXP(-$DB$14*CV24^2) -> 0.97655322 | DB24: =1+CW24+CX24-CY24+CZ24*DA24 -> 0.93056069 | DC24: =DB24-CU24 -> 0.13056069 | DD24: 0.85 | DE24: =0.27*CT24/DD24/$CS$19 -> 0.17073241 | DF24: =($CV$13+$CX$13/$CS$19+$CZ$13/$CS$19^3+$DB$13/$CS$19^4+$DD$13/$CS$19^5)*DE24 -> -0.074813576 | DG24: =($DF$13+$DH$13/$CS$19+$CV$14/$CS$19^2)*DE24^2 -> 0.0049719001 | DH24: =$CX$14*($DH$13/$CS$19+$CV$14/$CS$19^2)*DE24^5 -> -5.7744418e-06 | DI24: =$CZ$14*(1+$DB$14*DE24^2)*DE24^2/$CS$19^3 -> 0.0040072677 | DJ24: =EXP(-$DB$14*DE24^2) -> 0.97920248 | DK24: =1+DF24+DG24-DH24+DI24*DJ24 -> 0.93408802 | DL24: =DK24-DD24 -> 0.084088025 | DM24: =(DL24-DC24)/(DD24-CU24) -> -0.92945322 | DN24: =CU24-DC24/DM24 -> 0.94047042 | DO24: =DD24 -> 0.85 | DP24: =0.27*CT24/DO24/$CS$19 -> 0.17073241 | DQ24: =($CV$13+$CX$13/$CS$19+$CZ$13/$CS$19^3+$DB$13/$CS$19^4+$DD$13/$CS$19^5)*DP24 -> -0.074813576 | DR24: =($DF$13+$DH$13/$CS$19+$CV$14/$CS$19^2)*DP24^2 -> 0.0049719001 | DS24: =$CX$14*($DH$13/$CS$19+$CV$14/$CS$19^2)*DP24^5 -> -5.7744418e-06 | DT24: =$CZ$14*(1+$DB$14*DP24^2)*(DP24^2/$CS$19^3) -> 0.0040072677 | DU24: =EXP(-$DB$14*DP24^2) -> 0.97920248 | DV24: =1+DQ24+DR24-DS24+DT24*DU24 -> 0.93408802 | DW24: =DV24-DO24 -> 0.084088025 | DX24: =DN24 -> 0.94047042 | DY24: =0.27*CT24/DX24/$CS$19 -> 0.15430847 | DZ24: =($CV$13+$CX$13/$CS$19+$CZ$13/$CS$19^3+$DB$13/$CS$19^4+$DD$13/$CS$19^5)*DY24 -> -0.067616736 | EA24: =($DF$13+$DH$13/$CS$19+$CV$14/$CS$19^2)*DY24^2 -> 0.0040613458 | EB24: =$CX$14*($DH$13/$CS$19+$CV$14/$CS$19^2)*DY24^5 -> -3.4824022e-06 | EC24: =$CZ$14*(1+$DB$14*DY24^2)*DY24^2/$CS$19^3 -> 0.0032610363 | ED24: =EXP(-$DB$14*DY24^2) -> 0.98297872 | EE24: =1+DZ24+EA24-EB24+EC24*ED24 -> 0.93965362 | EF24: =EE24-DX24 -> -0.00081679958 | EG24: =(EF24-DW24)/(DX24-DO24) -> -0.93848158 | EH24: =DO24-DW24/EG24 -> 0.93960008 | EL24: =K24 -> 594.3155 | EV24: =(EL24*$EP$19)/(DN24*10.73*$EK$19) -> 1.78872 | EW24: =EV24/67.0176 -> 0.026690302 | EX24: =EXP($ET$19*EW24^$EU$19) -> 1.0511214 | EY24: =$ES$19*10^-4*EX24 -> 0.013181261
C25: =E24 -> 706.05692 | D25: 515.4 | E25: =CL25 -> 739.1215 | F25: =D25-E25 -> -223.7215 | G25: =AVERAGE(C25,D25) -> 610.72846 | I25: =Sheet10!K24 -> 734.37474 | K25: =G25 -> 610.72846 | O25: =(($O$8*K25^1.0937)/27.64)*10^(11.172*$N$19) -> 91.441718 | R25: =$W$6*EXP($W$9*(1697-G25)) -> 1.2286276 | S25: =0.0283*AT25*($M$19)/K25 -> 0.026949817 | T25: =$O$3*($O$4+R25) -> 122.86276 | U25: =T25*5.615 -> 689.87439 | V25: =IF($O$5>0,S25*($O$10-O25)*$O$3,0) -> 427.31167 | W25: =$Y$15+$Z$14*(O25-$X$15) -> 0.80085583 | X25: =$W$7 -> 48.33 | Y25: =R25/$W$6 -> 1.0238563 | Z25: =X25*Y25 -> 49.482976 | AA25: =($O$4*$S$6)+(R25*Z25) -> 60.796149 | AB25: =$O$4+R25 -> 1.2286276 | AC25: =AA25/AB25 -> 49.482976 | AH25: =10.715*(O25+100)^-0.515 -> 0.7157203 | AI25: =5.44*(O25+150)^-0.338 -> 0.85154644 | AJ25: =AH25*$AG$19^AI25 -> 2.9593308 | AK25: =(($O$4*$S$6)/($O$4*$S$6+R25*Z25))*$S$7 -> 0 | AL25: =((R25*Z25)/($O$4*$S$6+R25*Z25))*AJ25 -> 2.9593308 | AM25: =AK25+AL25 -> 2.9593308 | AN25: =(($O$4*$S$6)/($O$4*$S$6+R25*Z25))*$S$8 -> 0 | AO25: =((R25*Z25)/($O$4*$S$6+R25*Z25))*$S$4 -> 30 | AP25: =AN25+AO25 -> 30 | AR25: =CT25 -> 0.91563487 | AT25: =EH25 -> 0.93804971 | AV25: =(U25)*(1/86400)/$S$10 -> 0.36598887 | AW25: =(V25)*(1/86400)/$S$10 -> 0.22669535 | AX25: =AV25+AW25 -> 0.59268423 | AY25: =AV25/AX25 -> 0.61751074 | AZ25: =1-AY25 -> 0.38248926 | BA25: =1.071-(0.2218*((AX25^2)/($S$9))) -> 0.60352377 | BB25: =IF(BA25<0.13,0.13,BA25) -> 0.60352377 | BC25: =1.938*AV25*(AC25/AP25)^(1/4) -> 0.8038135 | BD25: =1.938*AW25*(AC25/AP25)^(1/4) -> 0.49788613 | BE25: =120.872*$S$9*SQRT(AC25/AP25) -> 25.872699 | BF25: =0.15726*AM25*(1/(AC25*AP25^3))^(1/4) -> 0.013688533 | BG25: =0.0019+0.0322*BF25-0.6642*BF25^2+4.9951*BF25^3 -> 0.0022291276 | BH25: =1-10.0147*BF25+33.8696*BF25^2+277.2817*BF25^3 -> 0.869971 | BI25: =BG25/BH25 -> 0.002562301 | BJ25: =BC25*($K$19^0.1)*BI25 -> 0.0038454315 | BK25: =(BD25^0.575)*(14.7^0.1)*BE25 -> 22.668524 | BL25: =BJ25/BK25 -> 0.00016963749 | BM25: =(0.0047+1123.32*BL25+729489.64*BL25^2) -> 0.21624963 | BN25: =(1+1097.1566*BL25+722153.97*BL25^2) -> 1.2069002 | BO25: =SQRT(BM25/BN25) -> 0.42329389 | BP25: =(BD25*BF25^0.38)/BE25^2.14 -> 9.2355834e-05 | BQ25: =1.0886-69.9473*BP25+2334.3497*BP25^2-12896.683*BP25^3 -> 1.0821599 | BR25: =1-53.4401*BP25+1517.9369*BP25^2-8419.8115*BP25^3 -> 0.99507744 | BS25: =BQ25/BR25 -> 1.0875132 | BT25: =IF(V25<=0,1,(BO25*BS25)) -> 0.4603377 | BU25: =IF(V25>1,BO25*BS25,1) -> 0.4603377 | BV25: =IF($O$5=0,1,BU25) -> 0.4603377 | BW25: =AC25*AV25 -> 18.110219 | BX25: =EV25*AW25 -> 0.41738629 | BY25: =$S$10*(BW25+BX25)*86400 -> 34923.794 | BZ25: =(AM25^BT25)*EY25^(1-BT25) -> 0.15950035 | CA25: =2.2*10^-2*BY25/BZ25/$S$9 -> 28902.387 | CB25: =$CC$16/3.7065 -> 0.00016187778 | CC25: =5.0452/CA25 -> 0.00017455998 | CD25: =LOG(($CC$16^1.1098/2.8257)+(7.149/CA25)^0.8981) -> -3.1735527 | CE25: =-4*LOG(CB25-(CC25*CD25)) -> 12.580704 | CF25: =1/CE25^2 -> 0.0063181522 | CG25: =BT25*AC25+(1-BT25)*EV25 -> 23.772493 | CH25: =CF25*BY25^2/($S$9)^5/CG25 -> 2.520661e+09 | CI25: =(1/144)*(CG25+(CH25/74130000000)) -> 0.16532289 | CJ25: =CI25*$CJ$15 -> 33.064578 | CK25: =CK24+200 -> 1400 | CL25: =C25+CJ25 -> 739.1215 | CT25: =K25/$CR$19 -> 0.91563487 | CU25: 0.8 | CV25: =0.27*CT25/CU25/$CS$19 -> 0.18641292 | CW25: =($CV$13+$CX$13/$CS$19+$CZ$13/$CS$19^3+$DB$13/$CS$19^4+$DD$13/$CS$19^5)*CV25 -> -0.081684651 | CX25: =($DF$13+$DH$13/$CS$19+$CV$14/$CS$19^2)*CV25^2 -> 0.0059271031 | CY25: =$CX$14*($DH$13/$CS$19+$CV$14/$CS$19^2)*CV25^5 -> -8.9600454e-06 | CZ25: =$CZ$14*(1+$DB$14*CV25^2)*(CV25^2/$CS$19^3) -> 0.0047960371 | DA25: =EXP(-$DB$14*CV25^2) -> 0.97525667 | DB25: =1+CW25+CX25-CY25+CZ25*DA25 -> 0.92892878 | DC25: =DB25-CU25 -> 0.12892878 | DD25: 0.85 | DE25: =0.27*CT25/DD25/$CS$19 -> 0.17544746 | DF25: =($CV$13+$CX$13/$CS$19+$CZ$13/$CS$19^3+$DB$13/$CS$19^4+$DD$13/$CS$19^5)*DE25 -> -0.076879671 | DG25: =($DF$13+$DH$13/$CS$19+$CV$14/$CS$19^2)*DE25^2 -> 0.0052503058 | DH25: =$CX$14*($DH$13/$CS$19+$CV$14/$CS$19^2)*DE25^5 -> -6.6170668e-06 | DI25: =$CZ$14*(1+$DB$14*DE25^2)*DE25^2/$CS$19^3 -> 0.0042365355 | DJ25: =EXP(-$DB$14*DE25^2) -> 0.97805078 | DK25: =1+DF25+DG25-DH25+DI25*DJ25 -> 0.9325208 | DL25: =DK25-DD25 -> 0.082520798 | DM25: =(DL25-DC25)/(DD25-CU25) -> -0.92815962 | DN25: =CU25-DC25/DM25 -> 0.93890798 | DO25: =DD25 -> 0.85 | DP25: =0.27*CT25/DO25/$CS$19 -> 0.17544746 | DQ25: =($CV$13+$CX$13/$CS$19+$CZ$13/$CS$19^3+$DB$13/$CS$19^4+$DD$13/$CS$19^5)*DP25 -> -0.076879671 | DR25: =($DF$13+$DH$13/$CS$19+$CV$14/$CS$19^2)*DP25^2 -> 0.0052503058 | DS25: =$CX$14*($DH$13/$CS$19+$CV$14/$CS$19^2)*DP25^5 -> -6.6170668e-06 | DT25: =$CZ$14*(1+$DB$14*DP25^2)*(DP25^2/$CS$19^3) -> 0.0042365355 | DU25: =EXP(-$DB$14*DP25^2) -> 0.97805078 | DV25: =1+DQ25+DR25-DS25+DT25*DU25 -> 0.9325208 | DW25: =DV25-DO25 -> 0.082520798 | DX25: =DN25 -> 0.93890798 | DY25: =0.27*CT25/DX25/$CS$19 -> 0.15883382 | DZ25: =($CV$13+$CX$13/$CS$19+$CZ$13/$CS$19^3+$DB$13/$CS$19^4+$DD$13/$CS$19^5)*DY25 -> -0.069599707 | EA25: =($DF$13+$DH$13/$CS$19+$CV$14/$CS$19^2)*DY25^2 -> 0.00430305 | EB25: =$CX$14*($DH$13/$CS$19+$CV$14/$CS$19^2)*DY25^5 -> -4.0238797e-06 | EC25: =$CZ$14*(1+$DB$14*DY25^2)*DY25^2/$CS$19^3 -> 0.003458582 | ED25: =EXP(-$DB$14*DY25^2) -> 0.98197491 | EE25: =1+DZ25+EA25-EB25+EC25*ED25 -> 0.93810361 | EF25: =EE25-DX25 -> -0.00080437426 | EG25: =(EF25-DW25)/(DX25-DO25) -> -0.93720689 | EH25: =DO25-DW25/EG25 -> 0.93804971 | EL25: =K25 -> 610.72846 | EV25: =(EL25*$EP$19)/(DN25*10.73*$EK$19) -> 1.8411771 | EW25: =EV25/67.0176 -> 0.027473039 | EX25: =EXP($ET$19*EW25^$EU$19) -> 1.053105 | EY25: =$ES$19*10^-4*EX25 -> 0.013206135
C26: =E25 -> 739.1215 | D26: 515.5 | E26: =CL26 -> 772.52765 | F26: =D26-E26 -> -257.02765 | G26: =AVERAGE(C26,D26) -> 627.31075 | I26: =Sheet10!K25 -> 770.72356 | K26: =G26 -> 627.31075 | O26: =(($O$8*K26^1.0937)/27.64)*10^(11.172*$N$19) -> 94.160576 | R26: =$W$6*EXP($W$9*(1697-G26)) -> 1.2281855 | S26: =0.0283*AT26*($M$19)/K26 -> 0.026193843 | T26: =$O$3*($O$4+R26) -> 122.81855 | U26: =T26*5.615 -> 689.62615 | V26: =IF($O$5>0,S26*($O$10-O26)*$O$3,0) -> 408.20334 | W26: =$Y$15+$Z$14*(O26-$X$15) -> 0.80058394 | X26: =$W$7 -> 48.33 | Y26: =R26/$W$6 -> 1.0234879 | Z26: =X26*Y26 -> 49.46517 | AA26: =($O$4*$S$6)+(R26*Z26) -> 60.752404 | AB26: =$O$4+R26 -> 1.2281855 | AC26: =AA26/AB26 -> 49.46517 | AH26: =10.715*(O26+100)^-0.515 -> 0.71054115 | AI26: =5.44*(O26+150)^-0.338 -> 0.8483295 | AJ26: =AH26*$AG$19^AI26 -> 2.9222046 | AK26: =(($O$4*$S$6)/($O$4*$S$6+R26*Z26))*$S$7 -> 0 | AL26: =((R26*Z26)/($O$4*$S$6+R26*Z26))*AJ26 -> 2.9222046 | AM26: =AK26+AL26 -> 2.9222046 | AN26: =(($O$4*$S$6)/($O$4*$S$6+R26*Z26))*$S$8 -> 0 | AO26: =((R26*Z26)/($O$4*$S$6+R26*Z26))*$S$4 -> 30 | AP26: =AN26+AO26 -> 30 | AR26: =CT26 -> 0.94049587 | AT26: =EH26 -> 0.93649145 | AV26: =(U26)*(1/86400)/$S$10 -> 0.36585718 | AW26: =(V26)*(1/86400)/$S$10 -> 0.21655809 | AX26: =AV26+AW26 -> 0.58241527 | AY26: =AV26/AX26 -> 0.62817237 | AZ26: =1-AY26 -> 0.37182763 | BA26: =1.071-(0.2218*((AX26^2)/($S$9))) -> 0.6195826 | BB26: =IF(BA26<0.13,0.13,BA26) -> 0.6195826 | BC26: =1.938*AV26*(AC26/AP26)^(1/4) -> 0.80345197 | BD26: =1.938*AW26*(AC26/AP26)^(1/4) -> 0.47557909 | BE26: =120.872*$S$9*SQRT(AC26/AP26) -> 25.868044 | BF26: =0.15726*AM26*(1/(AC26*AP26^3))^(1/4) -> 0.013518019 | BG26: =0.0019+0.0322*BF26-0.6642*BF26^2+4.9951*BF26^3 -> 0.0022262455 | BH26: =1-10.0147*BF26+33.8696*BF26^2+277.2817*BF26^3 -> 0.87149527 | BI26: =BG26/BH26 -> 0.0025545124 | BJ26: =BC26*($K$19^0.1)*BI26 -> 0.0038320183 | BK26: =(BD26^0.575)*(14.7^0.1)*BE26 -> 22.074882 | BL26: =BJ26/BK26 -> 0.00017359179 | BM26: =(0.0047+1123.32*BL26+729489.64*BL26^2) -> 0.22168165 | BN26: =(1+1097.1566*BL26+722153.97*BL26^2) -> 1.2122188 | BO26: =SQRT(BM26/BN26) -> 0.4276361 | BP26: =(BD26*BF26^0.38)/BE26^2.14 -> 8.783258e-05 | BQ26: =1.0886-69.9473*BP26+2334.3497*BP26^2-12896.683*BP26^3 -> 1.0824743 | BR26: =1-53.4401*BP26+1517.9369*BP26^2-8419.8115*BP26^3 -> 0.99531792 | BS26: =BQ26/BR26 -> 1.0875664 | BT26: =IF(V26<=0,1,(BO26*BS26)) -> 0.46508266 | BU26: =IF(V26>1,BO26*BS26,1) -> 0.46508266 | BV26: =IF($O$5=0,1,BU26) -> 0.46508266 | BW26: =AC26*AV26 -> 18.097188 | BX26: =EV26*AW26 -> 0.41023436 | BY26: =$S$10*(BW26+BX26)*86400 -> 34885.75 | BZ26: =(AM26^BT26)*EY26^(1-BT26) -> 0.162859 | CA26: =2.2*10^-2*BY26/BZ26/$S$9 -> 28275.496 | CB26: =$CC$16/3.7065 -> 0.00016187778 | CC26: =5.0452/CA26 -> 0.00017843012 | CD26: =LOG(($CC$16^1.1098/2.8257)+(7.149/CA26)^0.8981) -> -3.1661889 | CE26: =-4*LOG(CB26-(CC26*CD26)) -> 12.55429 | CF26: =1/CE26^2 -> 0.0063447676 | CG26: =BT26*AC26+(1-BT26)*EV26 -> 24.018707 | CH26: =CF26*BY26^2/($S$9)^5/CG26 -> 2.499876e+09 | CI26: =(1/144)*(CG26+(CH26/74130000000)) -> 0.16703077 | CJ26: =CI26*$CJ$15 -> 33.406153 | CK26: =CK25+200 -> 1600 | CL26: =C26+CJ26 -> 772.52765 | CT26: =K26/$CR$19 -> 0.94049587 | CU26: 0.8 | CV26: =0.27*CT26/CU26/$CS$19 -> 0.19147434 | CW26: =($CV$13+$CX$13/$CS$19+$CZ$13/$CS$19^3+$DB$13/$CS$19^4+$DD$13/$CS$19^5)*CV26 -> -0.083902524 | CX26: =($DF$13+$DH$13/$CS$19+$CV$14/$CS$19^2)*CV26^2 -> 0.0062533339 | CY26: =$CX$14*($DH$13/$CS$19+$CV$14/$CS$19^2)*CV26^5 -> -1.0244318e-05 | CZ26: =$CZ$14*(1+$DB$14*CV26^2)*(CV26^2/$CS$19^3) -> 0.0050668208 | DA26: =EXP(-$DB$14*CV26^2) -> 0.9739127 | DB26: =1+CW26+CX26-CY26+CZ26*DA26 -> 0.92729569 | DC26: =DB26-CU26 -> 0.12729569 | DD26: 0.85 | DE26: =0.27*CT26/DD26/$CS$19 -> 0.18021114 | DF26: =($CV$13+$CX$13/$CS$19+$CZ$13/$CS$19^3+$DB$13/$CS$19^4+$DD$13/$CS$19^5)*DE26 -> -0.078967082 | DG26: =($DF$13+$DH$13/$CS$19+$CV$14/$CS$19^2)*DE26^2 -> 0.0055392854 | DH26: =$CX$14*($DH$13/$CS$19+$CV$14/$CS$19^2)*DE26^5 -> -7.5655128e-06 | DI26: =$CZ$14*(1+$DB$14*DE26^2)*DE26^2/$CS$19^3 -> 0.0044750581 | DJ26: =EXP(-$DB$14*DE26^2) -> 0.97685677 | DK26: =1+DF26+DG26-DH26+DI26*DJ26 -> 0.93095126 | DL26: =DK26-DD26 -> 0.08095126 | DM26: =(DL26-DC26)/(DD26-CU26) -> -0.9268887 | DN26: =CU26-DC26/DM26 -> 0.93733655 | DO26: =DD26 -> 0.85 | DP26: =0.27*CT26/DO26/$CS$19 -> 0.18021114 | DQ26: =($CV$13+$CX$13/$CS$19+$CZ$13/$CS$19^3+$DB$13/$CS$19^4+$DD$13/$CS$19^5)*DP26 -> -0.078967082 | DR26: =($DF$13+$DH$13/$CS$19+$CV$14/$CS$19^2)*DP26^2 -> 0.0055392854 | DS26: =$CX$14*($DH$13/$CS$19+$CV$14/$CS$19^2)*DP26^5 -> -7.5655128e-06 | DT26: =$CZ$14*(1+$DB$14*DP26^2)*(DP26^2/$CS$19^3) -> 0.0044750581 | DU26: =EXP(-$DB$14*DP26^2) -> 0.97685677 | DV26: =1+DQ26+DR26-DS26+DT26*DU26 -> 0.93095126 | DW26: =DV26-DO26 -> 0.08095126 | DX26: =DN26 -> 0.93733655 | DY26: =0.27*CT26/DX26/$CS$19 -> 0.16341993 | DZ26: =($CV$13+$CX$13/$CS$19+$CZ$13/$CS$19^3+$DB$13/$CS$19^4+$DD$13/$CS$19^5)*DY26 -> -0.071609306 | EA26: =($DF$13+$DH$13/$CS$19+$CV$14/$CS$19^2)*DY26^2 -> 0.004555127 | EB26: =$CX$14*($DH$13/$CS$19+$CV$14/$CS$19^2)*DY26^5 -> -4.6393298e-06 | EC26: =$CZ$14*(1+$DB$14*DY26^2)*DY26^2/$CS$19^3 -> 0.0036650207 | ED26: =EXP(-$DB$14*DY26^2) -> 0.98092912 | EE26: =1+DZ26+EA26-EB26+EC26*ED26 -> 0.93654559 | EF26: =EE26-DX26 -> -0.0007909625 | EG26: =(EF26-DW26)/(DX26-DO26) -> -0.93594519 | EH26: =DO26-DW26/EG26 -> 0.93649145 | EL26: =K26 -> 627.31075 | EV26: =(EL26*$EP$19)/(DN26*10.73*$EK$19) -> 1.8943386 | EW26: =EV26/67.0176 -> 0.028266286 | EX26: =EXP($ET$19*EW26^$EU$19) -> 1.0551355 | EY26: =$ES$19*10^-4*EX26 -> 0.013231598
C27: =E26 -> 772.52765 | D27: 515.6 | E27: =CL27 -> 806.27861 | F27: =D27-E27 -> -290.67861 | G27: =AVERAGE(C27,D27) -> 644.06382 | I27: =Sheet10!K26 -> 807.85222 | K27: =G27 -> 644.06382 | O27: =(($O$8*K27^1.0937)/27.64)*10^(11.172*$N$19) -> 96.914284 | R27: =$W$6*EXP($W$9*(1697-G27)) -> 1.227739 | S27: =0.0283*AT27*($M$19)/K27 -> 0.025469842 | T27: =$O$3*($O$4+R27) -> 122.7739 | U27: =T27*5.615 -> 689.37544 | V27: =IF($O$5>0,S27*($O$10-O27)*$O$3,0) -> 389.9069 | W27: =$Y$15+$Z$14*(O27-$X$15) -> 0.80030857 | X27: =$W$7 -> 48.33 | Y27: =R27/$W$6 -> 1.0231158 | Z27: =X27*Y27 -> 49.447188 | AA27: =($O$4*$S$6)+(R27*Z27) -> 60.70824 | AB27: =$O$4+R27 -> 1.227739 | AC27: =AA27/AB27 -> 49.447188 | AH27: =10.715*(O27+100)^-0.515 -> 0.70540642 | AI27: =5.44*(O27+150)^-0.338 -> 0.8451198 | AJ27: =AH27*$AG$19^AI27 -> 2.8856073 | AK27: =(($O$4*$S$6)/($O$4*$S$6+R27*Z27))*$S$7 -> 0 | AL27: =((R27*Z27)/($O$4*$S$6+R27*Z27))*AJ27 -> 2.8856073 | AM27: =AK27+AL27 -> 2.8856073 | AN27: =(($O$4*$S$6)/($O$4*$S$6+R27*Z27))*$S$8 -> 0 | AO27: =((R27*Z27)/($O$4*$S$6+R27*Z27))*$S$4 -> 30 | AP27: =AN27+AO27 -> 30 | AR27: =CT27 -> 0.96561293 | AT27: =EH27 -> 0.93492556 | AV27: =(U27)*(1/86400)/$S$10 -> 0.36572418 | AW27: =(V27)*(1/86400)/$S$10 -> 0.20685155 | AX27: =AV27+AW27 -> 0.57257573 | AY27: =AV27/AX27 -> 0.63873503 | AZ27: =1-AY27 -> 0.36126497 | BA27: =1.071-(0.2218*((AX27^2)/($S$9))) -> 0.63470658 | BB27: =IF(BA27<0.13,0.13,BA27) -> 0.63470658 | BC27: =1.938*AV27*(AC27/AP27)^(1/4) -> 0.80308687 | BD27: =1.938*AW27*(AC27/AP27)^(1/4) -> 0.45422145 | BE27: =120.872*$S$9*SQRT(AC27/AP27) -> 25.863341 | BF27: =0.15726*AM27*(1/(AC27*AP27^3))^(1/4) -> 0.013349935 | BG27: =0.0019+0.0322*BF27-0.6642*BF27^2+4.9951*BF27^3 -> 0.0022233782 | BH27: =1-10.0147*BF27+33.8696*BF27^2+277.2817*BF27^3 -> 0.87300039 | BI27: =BG27/BH27 -> 0.0025468238 | BJ27: =BC27*($K$19^0.1)*BI27 -> 0.0038187486 | BK27: =(BD27^0.575)*(14.7^0.1)*BE27 -> 21.495386 | BL27: =BJ27/BK27 -> 0.00017765434 | BM27: =(0.0047+1123.32*BL27+729489.64*BL27^2) -> 0.22728614 | BN27: =(1+1097.1566*BL27+722153.97*BL27^2) -> 1.2177066 | BO27: =SQRT(BM27/BN27) -> 0.43203124 | BP27: =(BD27*BF27^0.38)/BE27^2.14 -> 8.3522718e-05 | BQ27: =1.0886-69.9473*BP27+2334.3497*BP27^2-12896.683*BP27^3 -> 1.0827741 | BR27: =1-53.4401*BP27+1517.9369*BP27^2-8419.8115*BP27^3 -> 0.99554712 | BS27: =BQ27/BR27 -> 1.0876171 | BT27: =IF(V27<=0,1,(BO27*BS27)) -> 0.46988457 | BU27: =IF(V27>1,BO27*BS27,1) -> 0.46988457 | BV27: =IF($O$5=0,1,BU27) -> 0.46988457 | BW27: =AC27*AV27 -> 18.084032 | BX27: =EV27*AW27 -> 0.40299097 | BY27: =$S$10*(BW27+BX27)*86400 -> 34847.299 | BZ27: =(AM27^BT27)*EY27^(1-BT27) -> 0.16632177 | CA27: =2.2*10^-2*BY27/BZ27/$S$9 -> 27656.291 | CB27: =$CC$16/3.7065 -> 0.00016187778 | CC27: =5.0452/CA27 -> 0.00018242504 | CD27: =LOG(($CC$16^1.1098/2.8257)+(7.149/CA27)^0.8981) -> -3.158733 | CE27: =-4*LOG(CB27-(CC27*CD27)) -> 12.527516 | CF27: =1/CE27^2 -> 0.0063719162 | CG27: =BT27*AC27+(1-BT27)*EV27 -> 24.267249 | CH27: =CF27*BY27^2/($S$9)^5/CG27 -> 2.4793852e+09 | CI27: =(1/144)*(CG27+(CH27/74130000000)) -> 0.16875483 | CJ27: =CI27*$CJ$15 -> 33.750965 | CK27: =CK26+200 -> 1800 | CL27: =C27+CJ27 -> 806.27861 | CT27: =K27/$CR$19 -> 0.96561293 | CU27: 0.8 | CV27: =0.27*CT27/CU27/$CS$19 -> 0.19658789 | CW27: =($CV$13+$CX$13/$CS$19+$CZ$13/$CS$19^3+$DB$13/$CS$19^4+$DD$13/$CS$19^5)*CV27 -> -0.086143241 | CX27: =($DF$13+$DH$13/$CS$19+$CV$14/$CS$19^2)*CV27^2 -> 0.0065917993 | CY27: =$CX$14*($DH$13/$CS$19+$CV$14/$CS$19^2)*CV27^5 -> -1.1687294e-05 | CZ27: =$CZ$14*(1+$DB$14*CV27^2)*(CV27^2/$CS$19^3) -> 0.0053485103 | DA27: =EXP(-$DB$14*CV27^2) -> 0.97252029 | DB27: =1+CW27+CX27-CY27+CZ27*DA27 -> 0.92566178 | DC27: =DB27-CU27 -> 0.12566178 | DD27: 0.85 | DE27: =0.27*CT27/DD27/$CS$19 -> 0.1850239 | DF27: =($CV$13+$CX$13/$CS$19+$CZ$13/$CS$19^3+$DB$13/$CS$19^4+$DD$13/$CS$19^5)*DE27 -> -0.081075991 | DG27: =($DF$13+$DH$13/$CS$19+$CV$14/$CS$19^2)*DE27^2 -> 0.0058391025 | DH27: =$CX$14*($DH$13/$CS$19+$CV$14/$CS$19^2)*DE27^5 -> -8.6311619e-06 | DI27: =$CZ$14*(1+$DB$14*DE27^2)*DE27^2/$CS$19^3 -> 0.004723115 | DJ27: =EXP(-$DB$14*DE27^2) -> 0.97561952 | DK27: =1+DF27+DG27-DH27+DI27*DJ27 -> 0.92937971 | DL27: =DK27-DD27 -> 0.079379706 | DM27: =(DL27-DC27)/(DD27-CU27) -> -0.9256415 | DN27: =CU27-DC27/DM27 -> 0.93575642 | DO27: =DD27 -> 0.85 | DP27: =0.27*CT27/DO27/$CS$19 -> 0.1850239 | DQ27: =($CV$13+$CX$13/$CS$19+$CZ$13/$CS$19^3+$DB$13/$CS$19^4+$DD$13/$CS$19^5)*DP27 -> -0.081075991 | DR27: =($DF$13+$DH$13/$CS$19+$CV$14/$CS$19^2)*DP27^2 -> 0.0058391025 | DS27: =$CX$14*($DH$13/$CS$19+$CV$14/$CS$19^2)*DP27^5 -> -8.6311619e-06 | DT27: =$CZ$14*(1+$DB$14*DP27^2)*(DP27^2/$CS$19^3) -> 0.004723115 | DU27: =EXP(-$DB$14*DP27^2) -> 0.97561952 | DV27: =1+DQ27+DR27-DS27+DT27*DU27 -> 0.92937971 | DW27: =DV27-DO27 -> 0.079379706 | DX27: =DN27 -> 0.93575642 | DY27: =0.27*CT27/DX27/$CS$19 -> 0.16806757 | DZ27: =($CV$13+$CX$13/$CS$19+$CZ$13/$CS$19^3+$DB$13/$CS$19^4+$DD$13/$CS$19^5)*DY27 -> -0.073645866 | EA27: =($DF$13+$DH$13/$CS$19+$CV$14/$CS$19^2)*DY27^2 -> 0.0048179059 | EB27: =$CX$14*($DH$13/$CS$19+$CV$14/$CS$19^2)*DY27^5 -> -5.3376464e-06 | EC27: =$CZ$14*(1+$DB$14*DY27^2)*DY27^2/$CS$19^3 -> 0.0038806752 | ED27: =EXP(-$DB$14*DY27^2) -> 0.97984011 | EE27: =1+DZ27+EA27-EB27+EC27*ED27 -> 0.93497982 | EF27: =EE27-DX27 -> -0.00077660615 | EG27: =(EF27-DW27)/(DX27-DO27) -> -0.93469745 | EH27: =DO27-DW27/EG27 -> 0.93492556 | EL27: =K27 -> 644.06382 | EV27: =(EL27*$EP$19)/(DN27*10.73*$EK$19) -> 1.9482134 | EW27: =EV27/67.0176 -> 0.029070176 | EX27: =EXP($ET$19*EW27^$EU$19) -> 1.0572138 | EY27: =$ES$19*10^-4*EX27 -> 0.013257661
